Workbook

Sheet Summary
A1: Description | B1: Value | C1: Actual Load KVA
B2: As per the Sanction Letter | C2: Usage measured on 1of every month
A3: Utility Sanction Load KVA | B3: 14000 KVA | C3: 7760 KVA
A4: Utility Minimum Demand % | B4: 75
A6: Capacity Installed | B6: Transformer kW | C6: No of TX | D6: Catcher TX kW | E6: No. Of catcher | F6: Actual Load kW | G6: Generator kW | H6: No of DG | I6: Catcher DG kW | J6: No. Of catcher | K6: UPS kW | L6: UPS Config | M6: IT capacity Installed kW | N6: IT Power Sold in kW ( concidering unity as PF) | O6: Allocated IT Power to customer ( Taking 50% as divercity factor for rated power customer ) | P6: IT kW Usage | Q6: Avaialble IT kW Design-Used | R6: Available IT kW Design-Sold | S6: Available IT kW Design-Sold ( Allocated capacity) | T6: MAX Rack Capacity | U6: Racks which can be placed on floor | V6: Rack losss ( Cage+ non standard rack+ path) | W6: Available space | X6: Designed White Space ( in SQ FT) | Y6: Used White Space( in SQ FT) | Z6: Avaialble White Space ( in SQ FT)
B7: Mention the design kW capacity of Transformer | G7: Mention the design kW capacity of Generator | K7: Mention the design N capacity in kw in a N+N Configuration | M7: Installed including interfloor shared capacity | N7: Customer subscribed IT kW | O7: Allocated power | P7: Measured on 1st of every month | Q7: Measured on 1st of every month | R7: Measured on 1st of every month | S7: Measured on 1st of every month
A8: L1 | B8: =2750*0.9 -> 2475 | C8: 1 | D8: =2750*0.9 -> 2475 | E8: 1 | F8: 1046 | G8: =3000*0.8 -> 2400 | H8: 1 | I8: =3000*0.8 -> 2400 | J8: 1 | K8: 2160 | L8: Bank A ( 1250 KVA* 2) & Bank B (600 KVA *4 ) | M8: 2160 | N8: 2160 | O8: 2160 | P8: ='Noida-01'!U168 -> 954.80061 | Q8: =M8-P8 -> 1205.1994 | R8: =M8-N8 -> 0 | S8: =M8-O8 -> 0 | T8: 220 | U8: 220 | V8: 0 | W8: 0 | X8: 7384 | Y8: 7384 | Z8: =X8-Y8 -> 0
A9: L2 | B9: =2750*0.9 -> 2475 | C9: 1 | F9: 860 | G9: =3000*0.8 -> 2400 | H9: 1 | K9: 2160 | L9: Bank A ( 1250 KVA* 2) & Bank B (600 KVA *4 ) | M9: 2160 | N9: 2160 | O9: 2160 | P9: ='Noida-01'!U169 -> 737.80376 | Q9: =M9-P9 -> 1422.1962 | R9: =M9-N9 -> 0 | S9: =M9-O9 -> 0 | T9: 220 | U9: 220 | V9: 0 | W9: 0 | X9: 7384 | Y9: 7384 | Z9: =X9-Y9 -> 0
A10: L3 | B10: =2750*0.9 -> 2475 | C10: 1 | F10: 837 | G10: =3000*0.8 -> 2400 | H10: 1 | K10: 2160 | L10: Bank A ( 1250 KVA* 2) & Bank B (600 KVA *4 ) | M10: 2160 | N10: 2160 | O10: 2160 | P10: ='Noida-01'!U170 -> 914.58874 | Q10: =M10-P10 -> 1245.4113 | R10: =M10-N10 -> 0 | S10: =M10-O10 -> 0 | T10: 220 | U10: 220 | V10: 0 | W10: 0 | X10: 7384 | Y10: 7384 | Z10: =X10-Y10 -> 0
A11: L4 | B11: =2250*0.9 -> 2025 | C11: 1 | D11: =2500*0.9 -> 2250 | E11: 1 | F11: 1048 | G11: =2000*0.8 -> 1600 | H11: 1 | I11: =2500*0.8 -> 2000 | J11: 1 | K11: 1440 | L11: Bank A ( 400 KVA* 4) & Bank B (400 KVA *4 ) | M11: =1600*0.9 -> 1440 | N11: ='Noida-01'!T120 -> 1484.18 | O11: ='Noida-01'!Y120 -> #REF! | P11: ='Noida-01'!Z120 -> 614.16729 | Q11: =M11-P11 -> 825.83271 | R11: =M11-N11 -> -44.18 | S11: =M11-O11 -> #REF! | T11: 392 | U11: ='Noida-01'!L124 -> 313.95238 | V11: =69 -> 69 | W11: =T11-(U11+V11) -> 9.047619 | X11: 7300 | Y11: 7300 | Z11: =X11-Y11 -> 0
A12: L5 | B12: =2250*0.9 -> 2025 | C12: 1 | F12: 1062 | G12: =2250*0.8 -> 1800 | H12: 1 | K12: 1440 | L12: Bank A ( 400 KVA* 4) & Bank B (400 KVA *4 ) | M12: =800*0.9+100 -> 820 | N12: ='Noida-01'!T70 -> 933.87 | O12: ='Noida-01'!Y70 -> #REF! | P12: ='Noida-01'!Z70 -> 589.69917 | Q12: =M12-P12 -> 230.30083 | R12: =M12-N12 -> -113.87 | S12: =M12-O12 -> #REF! | T12: 353 | U12: ='Noida-01'!L74 -> 286.14286 | V12: 50 | W12: =T12-(U12+V12) -> 16.857143 | X12: 9200 | Y12: 9200 | Z12: =X12-Y12 -> 0
A13: L6 | M13: =720-100 -> 620 | N13: ='Noida-01'!T158 -> 1080.49 | O13: ='Noida-01'!Y158 -> #REF! | P13: ='Noida-01'!Z158 -> 500.87619 | Q13: =M13-P13 -> 119.12381 | R13: =M13-N13 -> -460.49 | S13: =M13-O13 -> #REF! | T13: 258 | U13: ='Noida-01'!L162 -> 244.71429 | V13: =34 -> 34 | W13: =T13-(U13+V13) -> -20.714286 | X13: 6000 | Y13: 6000 | Z13: =X13-Y13 -> 0
A14: L7 | B14: =2500*0.9 -> 2250 | C14: 1 | F14: 193 | G14: =2250*0.8 -> 1800 | H14: 1 | K14: 1700 | L14: Bank A ( 450 KVA* 4) & Bank B (450 KVA *4 ) | M14: 1400 | N14: ='Noida-01'!T226 -> 1436.8 | O14: ='Noida-01'!Y226 -> #REF! | P14: ='Noida-01'!Z226 -> 563.71504 | Q14: =M14-P14 -> 836.28496 | R14: =M14-N14 -> -36.8 | S14: =M14-O14 -> #REF! | T14: 261 | U14: ='Noida-01'!L231 -> 251.71429 | V14: 13 | W14: =T14-(U14+V14) -> -3.7142857 | X14: 6850 | Y14: 6850 | Z14: =X14-Y14 -> 0 | AA14: From L7 To L6 & l5 =150 KVA L6+ 120 KVA L5
A15: Total | K15: =SUM(K8:K14) -> 11060 | M15: =SUM(M8:M14) -> 10760 | N15: =SUM(N8:N14) -> 11415.34 | O15: =SUM(O8:O14) -> #REF! | P15: =SUM(P8:P14) -> 4875.6508 | Q15: =SUM(Q8:Q14) -> 5884.3492 | T15: =SUM(T8:T14) -> 1924 | U15: =SUM(U8:U14) -> 1756.5238 | V15: =SUM(V8:V14) -> 166
T17: =T15 -> 1924 | U17: =U15+V15 -> 1922.5238

Sheet Terminated
S1: Divisification | U1: 0.5 | V1: Rated to Consumed | X1: =#REF! -> #REF! | Z1: Actual PUE | AA1: 2.21 | AB1: Actual Unit Rate: | AC1: 10.35 | AD1: =+AA1*(AC1*(30.5*24-AF1)+AF1*20) -> 18246.92 | AE1: Genset Hr/Mo | AF1: 70.5
D2: Billing Model | F2: Space | O2: Power Capacity | Z2: Power Usage | AE2: Seating Space | AM2: Revenue (Monthly ) | AT2: Contract Information
A3: Floor | B3: Floor / Module | C3: Customer Name | D3: Power Subscription Model (Rated/Subscribed) | E3: Power Usage Model (Bundled / Metered) | F3: Subscription Mode | G3: Caged /Uncaged | H3: UoM | I3: Subscription | J3: In Use | K3: Yet to be given/ | L3: Billed | M3: Reserved Capacity if any (Non-Billable) | N3: Per Unit rate (MRC) | O3: Subscription Model | P3: UoM | Q3: Total Capacity Purchased | R3: Capacity in Use | S3: Capacity to be given | T3: Reserved Capacity if any | U3: Subscribed Capacity to be given in KW | V3: "Allocated" Capacity in KW (for KVA subscribed customer 50% diversity is used to make kW ) | W3: DC NW Infra | X3: Billable Additional Capacity | Y3: Additional Capacity Charges (MRC) | Z3: Usage Model | AA3: Multiplier | AB3: Uit rate Model (Fixed/Variable) | AC3: Unit Rate (per KW-HR) | AD3: No Of Units (KW-HR/ Month | AE3: Subscription Model | AF3: UoM | AG3: Subscription | AH3: In Use | AI3: Yet to be given | AJ3: Billed | AK3: Reserved Capacity if any | AL3: Per Unit rate | AM3: Space revenue including capacity | AN3: Additional Capacity Revenue | AO3: Power Usage revenue | AP3: Seating Space | AQ3: Any Other Items | AR3: Total Revenue | AS3: Billing Frequency | AT3: Sales Order ref No | AU3: Contract Start Date | AV3: Term of Contract (No of Years) | AW3: Current Exiry Date | AX3: Remarks if any | AZ3: Avg revenue /Rack /Month | BA3: Avg revenue /KW /Month | BB3: Net Revenue / Resvd KW | BC3: Proj Net Revenue / Resvd KW | BD3: Sold Net Revenue / Resvd KW | BF3: Total Rev (Cap + Power) | BG3: Capacity Revenue | BH3: Power Revenue | BI3: Cost of Power @ Act Usage | BJ3: Proj Cost of Power @ Reserv Cap | BK3: Cost of Power @ Design Use | BL3: Net Rev Total | BM3: Target Capacity Revenue | BN3: Capacity Surplus/Leakage | BO3: Power Surplus/Leakage | BP3: Contribution to Target | BQ3: KW | BS3: Power Surplus/Leakage | BT3: Capacity Surplus/Leakage | BU3: Total Surplus/Leakage | BV3: Power Surplus/Leakage / KW | BW3: Capacity Surplus/Leakage / KW | BX3: Total Surplus/Leakage / KW
A4: L5 | B4: L5A-05-11 | C4: KESCO (Kanpur Elec) | D4: Rated | E4: Bundled | F4: Rack | G4: Uncaged | H4: =IF(F4="Rack","No of Racks",(IF(F4="Space","Sq Ft","U Space"))) -> No of Racks | I4: 1 | J4: 0 | K4: =I4-J4 -> 1 | L4: 0 | N4: =((5736886/6)/12)*0+(420000+200000)/12 -> 51666.667 | O4: =D4 -> Rated | P4: KVA | Q4: 0 | R4: 0 | S4: =Q4-R4 -> 0 | U4: =IF(S4<=0,0,(IF(O4="Rated",(S4+T4)*'Noida-01'!#REF!,(S4+T4)))) -> 0 | V4: =IF(O4="Rated",Q4*'Noida-01'!#REF!,Q4) -> #REF! | W4: 0 | X4: =IF((S4*-1)>0, (S4*-1), 0) -> 0 | Y4: 0 | Z4: =E4 -> Bundled | AF4: =IF(AE4="No of Seats","No of Seats",(IF(AE4="Space","Sq Ft",""))) | AI4: =AG4-AH4 -> 0 | AM4: =N4*L4 -> 0 | AN4: =Y4*X4 -> 0 | AO4: =AD4*AC4*AA4 -> 0 | AP4: =AL4*AJ4 -> 0 | AQ4: =(1923838/6)/12 -> 26719.972 | AR4: =SUBTOTAL(9,AM4:AQ4) -> 26719.972 | AT4: 721003675 & 711080579 | AZ4: =IF(F4="Rack",AR4/I4,0)+IF(F4="U Space",AR4*40/I4,0)+IF(F4="Space",AR4*30/I4,0) -> 26719.972 | BA4: =+AR4/V4 -> #REF! | BB4: =+($AM4+$AN4+$AO4-BI4)/$V4 -> #REF! | BC4: =+($AM4+$AN4+$AO4-BJ4)/$V4 -> #REF! | BD4: =+($AM4+$AN4+IF(E4="Bundled",0,V4*0.85*AA4*AC4*30.5*24)-BK4)/$V4 -> #REF! | BF4: =+AM4+AN4+AO4 -> 0 | BG4: =+BF4-BH4 -> #REF! | BH4: =IF(E4="Bundled",MIN(V4*'Noida-01'!#REF!*(1+#REF!),BF4),AO4) -> #REF! | BI4: =IF($AD4>0,$AD4*'Noida-01'!#REF!*'Noida-01'!#REF!*(1+'Noida-01'!#REF!*(20/'Noida-01'!#REF!)/732),'Noida-01'!#REF!*W4) -> #REF! | BJ4: =IF($AD4>0,$AD4*'Noida-01'!#REF!*'Noida-01'!#REF!*(1+'Noida-01'!#REF!*(20/'Noida-01'!#REF!)/732),+'Noida-01'!#REF!*(W4+U4)) -> #REF! | BK4: =IF(E4="Bundled",'Noida-01'!#REF!*V4,'Noida-01'!#REF!*V4*0.85) -> #REF! | BL4: =+BB4*V4 -> #REF! | BM4: =+#REF!*V4 -> #REF! | BN4: =+BG4-BM4 -> #REF! | BO4: =+BH4-BI4 -> #REF! | BP4: =+BN4+BO4 -> #REF! | BQ4: =+V4 -> #REF! | BR4: =+BB4 -> #REF! | BS4: =IF(E4="Bundled",BK4-BI4,AO4-BI4) -> #REF! | BT4: =IF(E4="Bundled",+(BD4-#REF!)*V4,(AM4+AN4)-V4*#REF!) -> #REF! | BU4: =+BS4+BT4 -> #REF! | BV4: =+BS4/$BQ4 -> #REF! | BW4: =+BT4/$BQ4 -> #REF! | BX4: =+BU4/$BQ4 -> #REF!
A5: L4 | B5: L4-F-24 & L4-F-29 | C5: Adani Wilmar Limited | D5: Rated | E5: Bundled | F5: Rack | G5: Uncaged | H5: =IF(F5="Rack","No of Racks",(IF(F5="Space","Sq Ft","U Space"))) -> No of Racks | I5: 4 | J5: 0 | K5: 0 | L5: 0 | N5: =((175000+619000+619000+619000)/4)/12 -> 42333.333 | O5: =D5 -> Rated | P5: KVA | Q5: 0 | R5: 0 | S5: =Q5-R5 -> 0 | U5: =IF(S5<=0,0,(IF(O5="Rated",(S5+T5)*'Noida-01'!#REF!,(S5+T5)))) -> 0 | V5: =IF(O5="Rated",Q5*'Noida-01'!#REF!,Q5) -> #REF! | W5: 0 | X5: =IF((S5*-1)>0, (S5*-1), 0) -> 0 | Y5: =70000/12 -> 5833.3333 | Z5: =E5 -> Bundled | AI5: =AG5-AH5 -> 0 | AL5: =(0)/12 -> 0 | AM5: =N5*L5 -> 0 | AN5: =Y5*X5 -> 0 | AO5: =AD5*AC5*AA5 -> 0 | AP5: =AL5*AJ5 -> 0 | AQ5: =(140000+88000+45000)/12 -> 22750 | AR5: =SUBTOTAL(9,AM5:AQ5) -> 22750 | AT5: 121000894 & 121000913 | AU5: 43831 | AV5: 1 | AW5: 44196 | AZ5: =IF(F5="Rack",AR5/I5,0)+IF(F5="U Space",AR5*40/I5,0)+IF(F5="Space",AR5*30/I5,0) -> 5687.5 | BA5: =+AR5/V5 -> #REF! | BB5: =+($AM5+$AN5+$AO5-BI5)/$V5 -> #REF! | BC5: =+($AM5+$AN5+$AO5-BJ5)/$V5 -> #REF! | BD5: =+($AM5+$AN5+IF(E5="Bundled",0,V5*0.85*AA5*AC5*30.5*24)-BK5)/$V5 -> #REF! | BF5: =+AM5+AN5+AO5 -> 0 | BG5: =+BF5-BH5 -> #REF! | BH5: =IF(E5="Bundled",MIN(V5*'Noida-01'!#REF!*(1+#REF!),BF5),AO5) -> #REF! | BI5: =IF($AD5>0,$AD5*'Noida-01'!#REF!*'Noida-01'!#REF!*(1+'Noida-01'!#REF!*(20/'Noida-01'!#REF!)/732),'Noida-01'!#REF!*W5) -> #REF! | BJ5: =IF($AD5>0,$AD5*'Noida-01'!#REF!*'Noida-01'!#REF!*(1+'Noida-01'!#REF!*(20/'Noida-01'!#REF!)/732),+'Noida-01'!#REF!*(W5+U5)) -> #REF! | BK5: =IF(E5="Bundled",'Noida-01'!#REF!*V5,'Noida-01'!#REF!*V5*0.85) -> #REF! | BL5: =+BB5*V5 -> #REF! | BM5: =+#REF!*V5 -> #REF! | BN5: =+BG5-BM5 -> #REF! | BO5: =+BH5-BI5 -> #REF! | BP5: =+BN5+BO5 -> #REF! | BQ5: =+V5 -> #REF! | BR5: =+BB5 -> #REF! | BS5: =IF(E5="Bundled",BK5-BI5,AO5-BI5) -> #REF! | BT5: =IF(E5="Bundled",+(BD5-#REF!)*V5,(AM5+AN5)-V5*#REF!) -> #REF! | BU5: =+BS5+BT5 -> #REF! | BV5: =+BS5/$BQ5 -> #REF! | BW5: =+BT5/$BQ5 -> #REF! | BX5: =+BU5/$BQ5 -> #REF!
A6: L5 | B6: L5B-01-05 & L5B-01-06 | C6: MJUNCTION SERVICES LIMITED | D6: Rated | E6: Bundled | F6: Rack | G6: Uncaged | H6: =IF(F6="Rack","No of Racks",(IF(F6="Space","Sq Ft","U Space"))) -> No of Racks | I6: 2 | J6: 0 | K6: 0 | L6: 0 | N6: =800000/12 -> 66666.667 | O6: =D6 -> Rated | P6: KVA | Q6: 0 | R6: 0 | S6: =Q6-R6 -> 0 | U6: =IF(S6<=0,0,(IF(O6="Rated",(S6+T6)*'Noida-01'!#REF!,(S6+T6)))) -> 0 | V6: =IF(O6="Rated",Q6*'Noida-01'!#REF!,Q6) -> #REF! | W6: 0 | X6: =IF((S6*-1)>0, (S6*-1), 0) -> 0 | Y6: =80000/12 -> 6666.6667 | Z6: =E6 -> Bundled | AE6: No of Seats | AF6: =IF(AE6="No of Seats","No of Seats",(IF(AE6="Space","Sq Ft",""))) -> No of Seats | AG6: 0 | AH6: 0 | AI6: =AG6-AH6 -> 0 | AJ6: 0 | AL6: 0 | AM6: =N6*L6 -> 0 | AN6: =Y6*X6 -> 0 | AO6: =AD6*AC6*AA6 -> 0 | AP6: =AL6*AJ6 -> 0 | AR6: =SUBTOTAL(9,AM6:AQ6) -> 0 | AT6: 721004949 | AZ6: =IF(F6="Rack",AR6/I6,0)+IF(F6="U Space",AR6*40/I6,0)+IF(F6="Space",AR6*30/I6,0) -> 0 | BA6: =+AR6/V6 -> #REF! | BB6: =+($AM6+$AN6+$AO6-BI6)/$V6 -> #REF! | BC6: =+($AM6+$AN6+$AO6-BJ6)/$V6 -> #REF! | BD6: =+($AM6+$AN6+IF(E6="Bundled",0,V6*0.85*AA6*AC6*30.5*24)-BK6)/$V6 -> #REF! | BF6: =+AM6+AN6+AO6 -> 0 | BG6: =+BF6-BH6 -> #REF! | BH6: =IF(E6="Bundled",MIN(V6*'Noida-01'!#REF!*(1+#REF!),BF6),AO6) -> #REF! | BI6: =IF($AD6>0,$AD6*'Noida-01'!#REF!*'Noida-01'!#REF!*(1+'Noida-01'!#REF!*(20/'Noida-01'!#REF!)/732),'Noida-01'!#REF!*W6) -> #REF! | BJ6: =IF($AD6>0,$AD6*'Noida-01'!#REF!*'Noida-01'!#REF!*(1+'Noida-01'!#REF!*(20/'Noida-01'!#REF!)/732),+'Noida-01'!#REF!*(W6+U6)) -> #REF! | BK6: =IF(E6="Bundled",'Noida-01'!#REF!*V6,'Noida-01'!#REF!*V6*0.85) -> #REF! | BL6: =+BB6*V6 -> #REF! | BM6: =+#REF!*V6 -> #REF! | BN6: =+BG6-BM6 -> #REF! | BO6: =+BH6-BI6 -> #REF! | BP6: =+BN6+BO6 -> #REF! | BQ6: =+V6 -> #REF! | BR6: =+BB6 -> #REF! | BS6: =IF(E6="Bundled",BK6-BI6,AO6-BI6) -> #REF! | BT6: =IF(E6="Bundled",+(BD6-#REF!)*V6,(AM6+AN6)-V6*#REF!) -> #REF! | BU6: =+BS6+BT6 -> #REF! | BV6: =+BS6/$BQ6 -> #REF! | BW6: =+BT6/$BQ6 -> #REF! | BX6: =+BU6/$BQ6 -> #REF!
A7: L4 | B7: L4-E-29 | C7: E2 Info Solution | D7: Rated | E7: Bundled | F7: U space | G7: Uncaged | H7: =IF(F7="Rack","No of Racks",(IF(F7="Space","Sq Ft","U Space"))) -> U Space | I7: 2 | J7: 0 | K7: =I7-J7 -> 2 | L7: 0 | N7: =55000/12/2 -> 2291.6667 | O7: =D7 -> Rated | P7: KVA | Q7: 0 | R7: 0 | S7: =Q7-R7 -> 0 | U7: =IF(S7<=0,0,(IF(O7="Rated",(S7+T7)*$U$1,(S7+T7)))) -> 0 | V7: =IF(O7="Rated",Q7*$U$1,Q7) -> 0 | X7: =IF((S7*-1)>0, (S7*-1), 0) -> 0 | Y7: =90000/12 -> 7500 | Z7: =E7 -> Bundled | AI7: =AG7-AH7 -> 0 | AL7: =(0)/12 -> 0 | AM7: =N7*L7 -> 0 | AN7: =Y7*X7 -> 0 | AO7: =AD7*AC7*AA7 -> 0 | AP7: =AL7*AJ7 -> 0 | AQ7: =0/12 -> 0 | AR7: =SUBTOTAL(9,AM7:AQ7) -> 0 | AZ7: =IF(F7="Rack",AR7/I7,0)+IF(F7="U Space",AR7*40/I7,0)+IF(F7="Space",AR7*30/I7,0) -> 0 | BA7: =+AR7/V7 -> #DIV/0! | BB7: =+($AM7+$AN7+$AO7-BI7)/$V7 -> #DIV/0! | BC7: =+($AM7+$AN7+$AO7-BJ7)/$V7 -> #DIV/0! | BD7: =+($AM7+$AN7+IF(E7="Bundled",0,V7*0.85*AA7*AC7*30.5*24)-BK7)/$V7 -> #DIV/0! | BF7: =+AM7+AN7+AO7 -> 0 | BG7: =+BF7-BH7 -> #REF! | BH7: =IF(E7="Bundled",MIN(V7*$AD$1*(1+#REF!),BF7),AO7) -> #REF! | BI7: =IF($AD7>0,$AD7*$AA$1*$AC$1*(1+$AF$1*(20/$AC$1)/732),$AD$1*W7) -> 0 | BJ7: =IF($AD7>0,$AD7*$AA$1*$AC$1*(1+$AF$1*(20/$AC$1)/732),+$AD$1*(W7+U7)) -> 0 | BK7: =IF(E7="Bundled",$AD$1*V7,$AD$1*V7*0.85) -> 0 | BL7: =+BB7*V7 -> #DIV/0! | BM7: =+#REF!*V7 -> #REF! | BN7: =+BG7-BM7 -> #REF! | BO7: =+BH7-BI7 -> #REF! | BP7: =+BN7+BO7 -> #REF! | BQ7: =+V7 -> 0 | BR7: =+BB7 -> #DIV/0! | BS7: =IF(E7="Bundled",BK7-BI7,AO7-BI7) -> 0 | BT7: =IF(E7="Bundled",+(BD7-#REF!)*V7,(AM7+AN7)-V7*#REF!) -> #DIV/0! | BU7: =+BS7+BT7 -> #DIV/0! | BV7: =+BS7/$BQ7 -> #DIV/0! | BW7: =+BT7/$BQ7 -> #DIV/0! | BX7: =+BU7/$BQ7 -> #DIV/0!
A8: L6 | B8: L6-F-25 | C8: NGC Broadband | D8: Rated | E8: Bundled | F8: U space | G8: Uncaged | H8: =IF(F8="Rack","No of Racks",(IF(F8="Space","Sq Ft","U Space"))) -> U Space | I8: 2 | J8: 2 | K8: =I8-J8 -> 0 | L8: 2 | N8: =(35000)/12 -> 2916.6667 | O8: =D8 -> Rated | P8: KVA | Q8: 0.5 | R8: 0.28 | S8: =Q8-R8 -> 0.22 | U8: =IF(S8<=0,0,(IF(O8="Rated",(S8+T8)*$U$1,(S8+T8)))) -> 0.11 | V8: =IF(O8="Rated",Q8*$U$1,Q8) -> 0.25 | X8: =IF((S8*-1)>0, (S8*-1), 0) -> 0 | Y8: =99000/12 -> 8250 | Z8: =E8 -> Bundled | AF8: =IF(AE8="No of Seats","No of Seats",(IF(AE8="Space","Sq Ft",""))) | AI8: =AG8-AH8 -> 0 | AM8: =N8*L8 -> 5833.3333 | AN8: =Y8*X8 -> 0 | AO8: =AD8*AC8*AA8 -> 0 | AP8: =AL8*AJ8 -> 0 | AQ8: 0 | AR8: =SUBTOTAL(9,AM8:AQ8) -> 5833.3333 | AZ8: =IF(F8="Rack",AR8/I8,0)+IF(F8="U Space",AR8*40/I8,0)+IF(F8="Space",AR8*30/I8,0) -> 116666.67 | BA8: =+AR8/V8 -> 23333.333 | BB8: =+($AM8+$AN8+$AO8-BI8)/$V8 -> 23333.333 | BC8: =+($AM8+$AN8+$AO8-BJ8)/$V8 -> 15304.688 | BD8: =+($AM8+$AN8+IF(E8="Bundled",0,V8*0.85*AA8*AC8*30.5*24)-BK8)/$V8 -> 5086.4131 | BF8: =+AM8+AN8+AO8 -> 5833.3333 | BG8: =+BF8-BH8 -> #REF! | BH8: =IF(E8="Bundled",MIN(V8*$AD$1*(1+#REF!),BF8),AO8) -> #REF! | BI8: =IF($AD8>0,$AD8*$AA$1*$AC$1*(1+$AF$1*(20/$AC$1)/732),$AD$1*W8) -> 0 | BJ8: =IF($AD8>0,$AD8*$AA$1*$AC$1*(1+$AF$1*(20/$AC$1)/732),+$AD$1*(W8+U8)) -> 2007.1612 | BK8: =IF(E8="Bundled",$AD$1*V8,$AD$1*V8*0.85) -> 4561.7301 | BL8: =+BB8*V8 -> 5833.3333 | BM8: =+#REF!*V8 -> #REF! | BN8: =+BG8-BM8 -> #REF! | BO8: =+BH8-BI8 -> #REF! | BP8: =+BN8+BO8 -> #REF! | BQ8: =+V8 -> 0.25 | BR8: =+BB8 -> 23333.333 | BS8: =IF(E8="Bundled",BK8-BI8,AO8-BI8) -> 4561.7301 | BT8: =IF(E8="Bundled",+(BD8-#REF!)*V8,(AM8+AN8)-V8*#REF!) -> #REF! | BU8: =+BS8+BT8 -> #REF! | BV8: =+BS8/$BQ8 -> 18246.92 | BW8: =+BT8/$BQ8 -> #REF! | BX8: =+BU8/$BQ8 -> #REF!
A9: L6 | B9: L6-D-30, L6-D-29 | C9: ECSO | D9: Rated | E9: Bundled | F9: Rack | G9: Uncaged | H9: =IF(F9="Rack","No of Racks",(IF(F9="Space","Sq Ft","U Space"))) -> No of Racks | I9: 2 | J9: 0 | K9: =I9-J9 -> 2 | L9: 0 | N9: =(580000)/12 -> 48333.333 | O9: =D9 -> Rated | P9: KVA | Q9: 0 | R9: 0 | S9: =Q9-R9 -> 0 | U9: =IF(S9<=0,0,(IF(O9="Rated",(S9+T9)*$U$1,(S9+T9)))) -> 0 | V9: =IF(O9="Rated",Q9*$U$1,Q9) -> 0 | W9: 0 | X9: =IF((S9*-1)>0, (S9*-1), 0) -> 0 | Y9: =110000/12 -> 9166.6667 | Z9: =E9 -> Bundled | AI9: =AG9-AH9 -> 0 | AL9: =(0)/12 -> 0 | AM9: =N9*L9 -> 0 | AN9: =Y9*X9 -> 0 | AO9: =AD9*AC9*AA9 -> 0 | AP9: =AL9*AJ9 -> 0 | AQ9: =0/12 -> 0 | AR9: =SUBTOTAL(9,AM9:AQ9) -> 0 | AZ9: =IF(F9="Rack",AR9/I9,0)+IF(F9="U Space",AR9*40/I9,0)+IF(F9="Space",AR9*30/I9,0) -> 0 | BA9: =+AR9/V9 -> #DIV/0! | BB9: =+($AM9+$AN9+$AO9-BI9)/$V9 -> #DIV/0! | BC9: =+($AM9+$AN9+$AO9-BJ9)/$V9 -> #DIV/0! | BD9: =+($AM9+$AN9+IF(E9="Bundled",0,V9*0.85*AA9*AC9*30.5*24)-BK9)/$V9 -> #DIV/0! | BF9: =+AM9+AN9+AO9 -> 0 | BG9: =+BF9-BH9 -> #REF! | BH9: =IF(E9="Bundled",MIN(V9*$AD$1*(1+#REF!),BF9),AO9) -> #REF! | BI9: =IF($AD9>0,$AD9*$AA$1*$AC$1*(1+$AF$1*(20/$AC$1)/732),$AD$1*W9) -> 0 | BJ9: =IF($AD9>0,$AD9*$AA$1*$AC$1*(1+$AF$1*(20/$AC$1)/732),+$AD$1*(W9+U9)) -> 0 | BK9: =IF(E9="Bundled",$AD$1*V9,$AD$1*V9*0.85) -> 0 | BL9: =+BB9*V9 -> #DIV/0! | BM9: =+#REF!*V9 -> #REF! | BN9: =+BG9-BM9 -> #REF! | BO9: =+BH9-BI9 -> #REF! | BP9: =+BN9+BO9 -> #REF! | BQ9: =+V9 -> 0 | BR9: =+BB9 -> #DIV/0! | BS9: =IF(E9="Bundled",BK9-BI9,AO9-BI9) -> 0 | BT9: =IF(E9="Bundled",+(BD9-#REF!)*V9,(AM9+AN9)-V9*#REF!) -> #DIV/0! | BU9: =+BS9+BT9 -> #DIV/0! | BV9: =+BS9/$BQ9 -> #DIV/0! | BW9: =+BT9/$BQ9 -> #DIV/0! | BX9: =+BU9/$BQ9 -> #DIV/0!
A10: L5 | B10: Server Hall 5A L5A-01-08 | C10: RACSANN TECHNOLOGIES PVT LTD | D10: Rated | E10: Bundled | F10: U space | G10: Uncaged | H10: =IF(F10="Rack","No of Racks",(IF(F10="Space","Sq Ft","U Space"))) -> U Space | I10: 5 | J10: 5 | K10: =I10-J10 -> 0 | L10: 5 | N10: =(150000/5)/12 -> 2500 | O10: =D10 -> Rated | P10: KVA | Q10: 1.25 | R10: 1.01 | S10: =Q10-R10 -> 0.24 | U10: =IF(S10<=0,0,(IF(O10="Rated",(S10+T10)*$V$1,(S10+T10)))) -> #VALUE! | V10: =IF(O10="Rated",Q10*$V$1,Q10) -> #VALUE! | X10: =IF((S10*-1)>0, (S10*-1), 0) -> 0 | Y10: =105000/12 -> 8750 | Z10: =E10 -> Bundled | AF10: =IF(AE10="No of Seats","No of Seats",(IF(AE10="Space","Sq Ft",""))) | AI10: =AG10-AH10 -> 0 | AM10: =N10*L10 -> 12500 | AN10: =Y10*X10 -> 0 | AO10: =AD10*AC10*AA10 -> 0 | AP10: =AL10*AJ10 -> 0 | AQ10: =(90000)/12 -> 7500 | AR10: =SUBTOTAL(9,AM10:AQ10) -> 20000 | AT10: 121001215 | AZ10: =IF(F10="Rack",AR10/I10,0)+IF(F10="U Space",AR10*40/I10,0)+IF(F10="Space",AR10*30/I10,0) -> 160000 | BA10: =+AR10/V10 -> #VALUE! | BB10: =+($AM10+$AN10+$AO10-BI10)/$V10 -> #VALUE! | BC10: =+($AM10+$AN10+$AO10-BJ10)/$V10 -> #VALUE! | BD10: =+($AM10+$AN10+IF(E10="Bundled",0,V10*0.85*AA10*AC10*30.5*24)-BK10)/$V10 -> #VALUE! | BF10: =+AM10+AN10+AO10 -> 12500 | BG10: =+BF10-BH10 -> #VALUE! | BH10: =IF(E10="Bundled",MIN(V10*$AE$1*(1+#REF!),BF10),AO10) -> #VALUE! | BI10: =IF($AD10>0,$AD10*$AB$1*$AD$1*(1+$AG$1*(20/$AD$1)/732),$AE$1*W10) -> #VALUE! | BJ10: =IF($AD10>0,$AD10*$AB$1*$AD$1*(1+$AG$1*(20/$AD$1)/732),+$AE$1*(W10+U10)) -> #VALUE! | BK10: =IF(E10="Bundled",$AE$1*V10,$AE$1*V10*0.85) -> #VALUE! | BL10: =+BB10*V10 -> #VALUE! | BM10: =+#REF!*V10 -> #REF! | BN10: =+BG10-BM10 -> #VALUE! | BO10: =+BH10-BI10 -> #VALUE! | BP10: =+BN10+BO10 -> #VALUE! | BQ10: =+V10 -> #VALUE! | BR10: =+BB10 -> #VALUE! | BS10: =IF(E10="Bundled",BK10-BI10,AO10-BI10) -> #VALUE! | BT10: =IF(E10="Bundled",+(BD10-#REF!)*V10,(AM10+AN10)-V10*#REF!) -> #VALUE! | BU10: =+BS10+BT10 -> #VALUE! | BV10: =+BS10/$BQ10 -> #VALUE! | BW10: =+BT10/$BQ10 -> #VALUE! | BX10: =+BU10/$BQ10 -> #VALUE!
A11: L4 | B11: Server Hall L4 L4-D-29 | C11: Balaji Teleworks | D11: Rated | E11: Bundled | F11: U space | G11: Uncaged | H11: =IF(F11="Rack","No of Racks",(IF(F11="Space","Sq Ft","U Space"))) -> U Space | I11: 6 | J11: 6 | K11: =I11-J11 -> 0 | L11: 6 | N11: =(230000/6)/12 -> 3194.4444 | O11: =D11 -> Rated | P11: KVA | Q11: =500/900 -> 0.55555556 | R11: 1.11 | S11: =Q11-R11 -> -0.55444444 | U11: =IF(S11<=0,0,(IF(O11="Rated",(S11+T11)*$V$1,(S11+T11)))) -> 0 | V11: =IF(O11="Rated",Q11*$V$1,Q11) -> #VALUE! | X11: =IF((S11*-1)>0, (S11*-1), 0) -> 0.55444444 | Y11: =99000/12 -> 8250 | Z11: =E11 -> Bundled | AI11: =AG11-AH11 -> 0 | AL11: =(0)/12 -> 0 | AM11: =N11*L11 -> 19166.667 | AN11: =Y11*X11 -> 4574.1667 | AO11: =AD11*AC11*AA11 -> 0 | AP11: =AL11*AJ11 -> 0 | AQ11: =0/12 -> 0 | AR11: =SUBTOTAL(9,AM11:AQ11) -> 23740.833 | AZ11: =IF(F11="Rack",AR11/I11,0)+IF(F11="U Space",AR11*40/I11,0)+IF(F11="Space",AR11*30/I11,0) -> 158272.22 | BA11: =+AR11/V11 -> #VALUE! | BB11: =+($AM11+$AN11+$AO11-BI11)/$V11 -> #VALUE! | BC11: =+($AM11+$AN11+$AO11-BJ11)/$V11 -> #VALUE! | BD11: =+($AM11+$AN11+IF(E11="Bundled",0,V11*0.85*AA11*AC11*30.5*24)-BK11)/$V11 -> #VALUE! | BF11: =+AM11+AN11+AO11 -> 23740.833 | BG11: =+BF11-BH11 -> #VALUE! | BH11: =IF(E11="Bundled",MIN(V11*$AE$1*(1+#REF!),BF11),AO11) -> #VALUE! | BI11: =IF($AD11>0,$AD11*$AB$1*$AD$1*(1+$AG$1*(20/$AD$1)/732),$AE$1*W11) -> #VALUE! | BJ11: =IF($AD11>0,$AD11*$AB$1*$AD$1*(1+$AG$1*(20/$AD$1)/732),+$AE$1*(W11+U11)) -> #VALUE! | BK11: =IF(E11="Bundled",$AE$1*V11,$AE$1*V11*0.85) -> #VALUE! | BL11: =+BB11*V11 -> #VALUE! | BM11: =+#REF!*V11 -> #REF! | BN11: =+BG11-BM11 -> #VALUE! | BO11: =+BH11-BI11 -> #VALUE! | BP11: =+BN11+BO11 -> #VALUE! | BQ11: =+V11 -> #VALUE! | BR11: =+BB11 -> #VALUE! | BS11: =IF(E11="Bundled",BK11-BI11,AO11-BI11) -> #VALUE! | BT11: =IF(E11="Bundled",+(BD11-#REF!)*V11,(AM11+AN11)-V11*#REF!) -> #VALUE! | BU11: =+BS11+BT11 -> #VALUE! | BV11: =+BS11/$BQ11 -> #VALUE! | BW11: =+BT11/$BQ11 -> #VALUE! | BX11: =+BU11/$BQ11 -> #VALUE!
A12: L6 | B12: Server Hall L6 L6-E-03 | C12: SAIKRITI TECHSOFT PVT LTD | D12: Rated | E12: Bundled | F12: U space | G12: Uncaged | H12: =IF(F12="Rack","No of Racks",(IF(F12="Space","Sq Ft","U Space"))) -> U Space | I12: 21 | J12: 21 | K12: =I12-J12 -> 0 | L12: 21 | N12: =(350000/21)/12 -> 1388.8889 | O12: =D12 -> Rated | P12: KVA | Q12: 1.5 | R12: 3.38 | S12: =Q12-R12 -> -1.88 | U12: =IF(S12<=0,0,(IF(O12="Rated",(S12+T12)*$V$1,(S12+T12)))) -> 0 | V12: =IF(O12="Rated",Q12*$V$1,Q12) -> #VALUE! | X12: =IF((S12*-1)>0, (S12*-1), 0) -> 1.88 | Y12: =100000/12 -> 8333.3333 | Z12: =E12 -> Bundled | AF12: =IF(AE12="No of Seats","No of Seats",(IF(AE12="Space","Sq Ft",""))) | AI12: =AG12-AH12 -> 0 | AM12: =N12*L12 -> 29166.667 | AN12: =Y12*X12 -> 15666.667 | AO12: =AD12*AC12*AA12 -> 0 | AP12: =AL12*AJ12 -> 0 | AQ12: 0 | AR12: =SUBTOTAL(9,AM12:AQ12) -> 44833.333 | AZ12: =IF(F12="Rack",AR12/I12,0)+IF(F12="U Space",AR12*40/I12,0)+IF(F12="Space",AR12*30/I12,0) -> 85396.825 | BA12: =+AR12/V12 -> #VALUE! | BB12: =+($AM12+$AN12+$AO12-BI12)/$V12 -> #VALUE! | BC12: =+($AM12+$AN12+$AO12-BJ12)/$V12 -> #VALUE! | BD12: =+($AM12+$AN12+IF(E12="Bundled",0,V12*0.85*AA12*AC12*30.5*24)-BK12)/$V12 -> #VALUE! | BF12: =+AM12+AN12+AO12 -> 44833.333 | BG12: =+BF12-BH12 -> #VALUE! | BH12: =IF(E12="Bundled",MIN(V12*$AE$1*(1+#REF!),BF12),AO12) -> #VALUE! | BI12: =IF($AD12>0,$AD12*$AB$1*$AD$1*(1+$AG$1*(20/$AD$1)/732),$AE$1*W12) -> #VALUE! | BJ12: =IF($AD12>0,$AD12*$AB$1*$AD$1*(1+$AG$1*(20/$AD$1)/732),+$AE$1*(W12+U12)) -> #VALUE! | BK12: =IF(E12="Bundled",$AE$1*V12,$AE$1*V12*0.85) -> #VALUE! | BL12: =+BB12*V12 -> #VALUE! | BM12: =+#REF!*V12 -> #REF! | BN12: =+BG12-BM12 -> #VALUE! | BO12: =+BH12-BI12 -> #VALUE! | BP12: =+BN12+BO12 -> #VALUE! | BQ12: =+V12 -> #VALUE! | BR12: =+BB12 -> #VALUE! | BS12: =IF(E12="Bundled",BK12-BI12,AO12-BI12) -> #VALUE! | BT12: =IF(E12="Bundled",+(BD12-#REF!)*V12,(AM12+AN12)-V12*#REF!) -> #VALUE! | BU12: =+BS12+BT12 -> #VALUE! | BV12: =+BS12/$BQ12 -> #VALUE! | BW12: =+BT12/$BQ12 -> #VALUE! | BX12: =+BU12/$BQ12 -> #VALUE!
A13: L6 | B13: Server Hall L6 L6-F-25 | C13: ACME DIGINET CORPORATION PVT LTD | D13: Rated | E13: Bundled | F13: U space | G13: Uncaged | H13: =IF(F13="Rack","No of Racks",(IF(F13="Space","Sq Ft","U Space"))) -> U Space | I13: 6 | J13: 6 | K13: =I13-J13 -> 0 | L13: 6 | N13: =29000/12 -> 2416.6667 | O13: =D13 -> Rated | P13: KVA | Q13: 1.5 | R13: 2.67 | S13: =Q13-R13 -> -1.17 | U13: =IF(S13<=0,0,(IF(O13="Rated",(S13+T13)*$V$1,(S13+T13)))) -> 0 | V13: =IF(O13="Rated",Q13*$V$1,Q13) -> #VALUE! | X13: =IF((S13*-1)>0, (S13*-1), 0) -> 1.17 | Z13: =E13 -> Bundled | AF13: =IF(AE13="No of Seats","No of Seats",(IF(AE13="Space","Sq Ft",""))) | AI13: =AG13-AH13 -> 0 | AM13: =N13*L13 -> 14500 | AN13: =Y13*X13 -> 0 | AO13: =AD13*AC13*AA13 -> 0 | AP13: =AL13*AJ13 -> 0 | AQ13: 0 | AR13: =SUBTOTAL(9,AM13:AQ13) -> 14500 | AZ13: =IF(F13="Rack",AR13/I13,0)+IF(F13="U Space",AR13*40/I13,0)+IF(F13="Space",AR13*30/I13,0) -> 96666.667 | BA13: =+AR13/V13 -> #VALUE! | BB13: =+($AM13+$AN13+$AO13-BI13)/$V13 -> #VALUE! | BC13: =+($AM13+$AN13+$AO13-BJ13)/$V13 -> #VALUE! | BD13: =+($AM13+$AN13+IF(E13="Bundled",0,V13*0.85*AA13*AC13*30.5*24)-BK13)/$V13 -> #VALUE! | BF13: =+AM13+AN13+AO13 -> 14500 | BG13: =+BF13-BH13 -> #VALUE! | BH13: =IF(E13="Bundled",MIN(V13*$AE$1*(1+#REF!),BF13),AO13) -> #VALUE! | BI13: =IF($AD13>0,$AD13*$AB$1*$AD$1*(1+$AG$1*(20/$AD$1)/732),$AE$1*W13) -> #VALUE! | BJ13: =IF($AD13>0,$AD13*$AB$1*$AD$1*(1+$AG$1*(20/$AD$1)/732),+$AE$1*(W13+U13)) -> #VALUE! | BK13: =IF(E13="Bundled",$AE$1*V13,$AE$1*V13*0.85) -> #VALUE! | BL13: =+BB13*V13 -> #VALUE! | BM13: =+#REF!*V13 -> #REF! | BN13: =+BG13-BM13 -> #VALUE! | BO13: =+BH13-BI13 -> #VALUE! | BP13: =+BN13+BO13 -> #VALUE! | BQ13: =+V13 -> #VALUE! | BR13: =+BB13 -> #VALUE! | BS13: =IF(E13="Bundled",BK13-BI13,AO13-BI13) -> #VALUE! | BT13: =IF(E13="Bundled",+(BD13-#REF!)*V13,(AM13+AN13)-V13*#REF!) -> #VALUE! | BU13: =+BS13+BT13 -> #VALUE! | BV13: =+BS13/$BQ13 -> #VALUE! | BW13: =+BT13/$BQ13 -> #VALUE! | BX13: =+BU13/$BQ13 -> #VALUE!
A14: L4 | B14: Server Hall L4 L4-D-29 | C14: NAS INTERNET SERVICES PVT LTD | D14: Rated | E14: Bundled | F14: U space | G14: Uncaged | H14: =IF(F14="Rack","No of Racks",(IF(F14="Space","Sq Ft","U Space"))) -> U Space | I14: 3 | J14: 3 | K14: =I14-J14 -> 0 | L14: 3 | N14: =(35000)/12 -> 2916.6667 | O14: =D14 -> Rated | P14: KVA | Q14: 0.75 | R14: 0.61 | S14: =Q14-R14 -> 0.14 | U14: =IF(S14<=0,0,(IF(O14="Rated",(S14+T14)*$V$1,(S14+T14)))) -> #VALUE! | V14: =IF(O14="Rated",Q14*$V$1,Q14) -> #VALUE! | X14: =IF((S14*-1)>0, (S14*-1), 0) -> 0 | Y14: =90000/12 -> 7500 | Z14: =E14 -> Bundled | AI14: =AG14-AH14 -> 0 | AL14: =(0)/12 -> 0 | AM14: =N14*L14 -> 8750 | AN14: =Y14*X14 -> 0 | AO14: =AD14*AC14*AA14 -> 0 | AP14: =AL14*AJ14 -> 0 | AQ14: =0/12 -> 0 | AR14: =SUBTOTAL(9,AM14:AQ14) -> 8750 | AZ14: =IF(F14="Rack",AR14/I14,0)+IF(F14="U Space",AR14*40/I14,0)+IF(F14="Space",AR14*30/I14,0) -> 116666.67 | BA14: =+AR14/V14 -> #VALUE! | BB14: =+($AM14+$AN14+$AO14-BI14)/$V14 -> #VALUE! | BC14: =+($AM14+$AN14+$AO14-BJ14)/$V14 -> #VALUE! | BD14: =+($AM14+$AN14+IF(E14="Bundled",0,V14*0.85*AA14*AC14*30.5*24)-BK14)/$V14 -> #VALUE! | BF14: =+AM14+AN14+AO14 -> 8750 | BG14: =+BF14-BH14 -> #VALUE! | BH14: =IF(E14="Bundled",MIN(V14*$AE$1*(1+#REF!),BF14),AO14) -> #VALUE! | BI14: =IF($AD14>0,$AD14*$AB$1*$AD$1*(1+$AG$1*(20/$AD$1)/732),$AE$1*W14) -> #VALUE! | BJ14: =IF($AD14>0,$AD14*$AB$1*$AD$1*(1+$AG$1*(20/$AD$1)/732),+$AE$1*(W14+U14)) -> #VALUE! | BK14: =IF(E14="Bundled",$AE$1*V14,$AE$1*V14*0.85) -> #VALUE! | BL14: =+BB14*V14 -> #VALUE! | BM14: =+#REF!*V14 -> #REF! | BN14: =+BG14-BM14 -> #VALUE! | BO14: =+BH14-BI14 -> #VALUE! | BP14: =+BN14+BO14 -> #VALUE! | BQ14: =+V14 -> #VALUE! | BR14: =+BB14 -> #VALUE! | BS14: =IF(E14="Bundled",BK14-BI14,AO14-BI14) -> #VALUE! | BT14: =IF(E14="Bundled",+(BD14-#REF!)*V14,(AM14+AN14)-V14*#REF!) -> #VALUE! | BU14: =+BS14+BT14 -> #VALUE! | BV14: =+BS14/$BQ14 -> #VALUE! | BW14: =+BT14/$BQ14 -> #VALUE! | BX14: =+BU14/$BQ14 -> #VALUE!
A15: L5 | B15: Server Hall 5A L5A-04-11 | C15: SIMPLE TELECOM PVT LTD | D15: Rated | E15: Bundled | F15: U space | G15: Uncaged | H15: =IF(F15="Rack","No of Racks",(IF(F15="Space","Sq Ft","U Space"))) -> U Space | I15: 11 | J15: 11 | K15: =I15-J15 -> 0 | L15: 11 | N15: =(120000)/11/12 -> 909.09091 | O15: =D15 -> Rated | P15: KVA | Q15: 1 | R15: 2.1 | S15: =Q15-R15 -> -1.1 | U15: =IF(S15<=0,0,(IF(O15="Rated",(S15+T15)*$V$1,(S15+T15)))) -> 0 | V15: =IF(O15="Rated",Q15*$V$1,Q15) -> #VALUE! | X15: =IF((S15*-1)>0, (S15*-1), 0) -> 1.1 | Z15: =E15 -> Bundled | BK15: =IF(E15="Bundled",$AE$1*V15,$AE$1*V15*0.85) -> #VALUE! | BQ15: =+V15 -> #VALUE!
A16: L7 | B16: L7-E-05 | C16: SWAKSH INFRATECH | D16: Rated | E16: Bundled | F16: Rack | G16: Uncaged | H16: =IF(F16="Rack","No of Racks",(IF(F16="Space","Sq Ft","U Space"))) -> No of Racks | I16: 1 | J16: 1 | K16: =I16-J16 -> 0 | L16: 1 | N16: =(450000)/12 -> 37500 | O16: =D16 -> Rated | P16: KVA | Q16: 3 | R16: 0 | S16: =Q16-R16 -> 3 | U16: =IF(S16<=0,0,(IF(O16="Rated",(S16+T16)*'Noida-01'!#REF!,(S16+T16)))) -> #REF! | V16: =IF(O16="Rated",Q16*'Noida-01'!#REF!,Q16) -> #REF! | W16: =AD16/31/24 -> 0 | X16: =IF((S16*-1)>0, (S16*-1), 0) -> 0 | Z16: =E16 -> Bundled | AI16: =AG16-AH16 -> 0 | AL16: =(0)/12 -> 0 | AM16: =N16*L16 -> 37500 | AN16: =Y16*X16 -> 0 | AO16: =AD16*AC16*AA16 -> 0 | AP16: =AL16*AJ16 -> 0 | AQ16: =0/12 -> 0 | AR16: =SUBTOTAL(9,AM16:AQ16) -> 37500 | AZ16: =IF(F16="Rack",AR16/I16,0)+IF(F16="U Space",AR16*40/I16,0)+IF(F16="Space",AR16*30/I16,0) -> 37500 | BA16: =+AR16/V16 -> #REF! | BB16: =+($AM16+$AN16+$AO16-BI16)/$V16 -> #REF! | BC16: =+($AM16+$AN16+$AO16-BJ16)/$V16 -> #REF! | BD16: =+($AM16+$AN16+IF(E16="Bundled",0,V16*0.85*AA16*AC16*30.5*24)-BK16)/$V16 -> #REF! | BF16: =+AM16+AN16+AO16 -> 37500 | BG16: =+BF16-BH16 -> #REF! | BH16: =IF(E16="Bundled",MIN(V16*'Noida-01'!#REF!*(1+#REF!),BF16),AO16) -> #REF! | BI16: =IF($AD16>0,$AD16*'Noida-01'!#REF!*'Noida-01'!#REF!*(1+'Noida-01'!#REF!*(20/'Noida-01'!#REF!)/732),'Noida-01'!#REF!*W16) -> #REF! | BJ16: =IF($AD16>0,$AD16*'Noida-01'!#REF!*'Noida-01'!#REF!*(1+'Noida-01'!#REF!*(20/'Noida-01'!#REF!)/732),+'Noida-01'!#REF!*(W16+U16)) -> #REF! | BK16: =IF(E16="Bundled",'Noida-01'!#REF!*V16,'Noida-01'!#REF!*V16*0.85) -> #REF! | BL16: =+BB16*V16 -> #REF! | BM16: =+#REF!*V16 -> #REF! | BN16: =+BG16-BM16 -> #REF! | BO16: =+BH16-BI16 -> #REF! | BP16: =+BN16+BO16 -> #REF! | BQ16: =+V16 -> #REF! | BR16: =+BB16 -> #REF! | BS16: =IF(E16="Bundled",BK16-BI16,AO16-BI16) -> #REF! | BT16: =IF(E16="Bundled",+(BD16-#REF!)*V16,(AM16+AN16)-V16*#REF!) -> #REF! | BU16: =+BS16+BT16 -> #REF! | BV16: =+BS16/$BQ16 -> #REF! | BW16: =+BT16/$BQ16 -> #REF! | BX16: =+BU16/$BQ16 -> #REF!
A17: L5 | B17: L5A-02-02, L5A-02-03, L5A-02-04, L5A-02-05, L5A-02-06 & L5A-02-10 | C17: L&T (RVNL) | D17: Rated | E17: Bundled | F17: Rack | G17: Uncaged | H17: =IF(F17="Rack","No of Racks",(IF(F17="Space","Sq Ft","U Space"))) -> No of Racks | I17: 6 | J17: 6 | K17: =I17-J17 -> 0 | L17: 6 | N17: =((3601628+672384)/6)/12 -> 59361.278 | O17: =D17 -> Rated | P17: KVA | Q17: 84.65 | R17: 84.65 | S17: =Q17-R17 -> 0 | U17: =IF(S17<=0,0,(IF(O17="Rated",(S17+T17)*'Noida-01'!#REF!,(S17+T17)))) -> 0 | V17: =IF(O17="Rated",Q17*'Noida-01'!#REF!,Q17) -> #REF! | W17: 14.66 | X17: =IF((S17*-1)>0, (S17*-1), 0) -> 0 | Y17: =92700/12 -> 7725 | Z17: =E17 -> Bundled | AF17: =IF(AE17="No of Seats","No of Seats",(IF(AE17="Space","Sq Ft",""))) | AI17: =AG17-AH17 -> 0 | AM17: =N17*L17 -> 356167.67 | AN17: =Y17*X17 -> 0 | AO17: =AD17*AC17*AA17 -> 0 | AP17: =AL17*AJ17 -> 0 | AR17: =SUBTOTAL(9,AM17:AQ17) -> 356167.67 | AT17: Renewal | AU17: 43922 | AV17: 1 | AW17: 44286 | AZ17: =IF(F17="Rack",AR17/I17,0)+IF(F17="U Space",AR17*40/I17,0)+IF(F17="Space",AR17*30/I17,0) -> 59361.278 | BA17: =+AR17/V17 -> #REF! | BB17: =+($AM17+$AN17+$AO17-BI17)/$V17 -> #REF! | BC17: =+($AM17+$AN17+$AO17-BJ17)/$V17 -> #REF! | BD17: =+($AM17+$AN17+IF(E17="Bundled",0,V17*0.85*AA17*AC17*30.5*24)-BK17)/$V17 -> #REF! | BF17: =+AM17+AN17+AO17 -> 356167.67 | BG17: =+BF17-BH17 -> #REF! | BH17: =IF(E17="Bundled",MIN(V17*'Noida-01'!#REF!*(1+#REF!),BF17),AO17) -> #REF! | BI17: =IF($AD17>0,$AD17*'Noida-01'!#REF!*'Noida-01'!#REF!*(1+'Noida-01'!#REF!*(20/'Noida-01'!#REF!)/732),'Noida-01'!#REF!*W17) -> #REF! | BJ17: =IF($AD17>0,$AD17*'Noida-01'!#REF!*'Noida-01'!#REF!*(1+'Noida-01'!#REF!*(20/'Noida-01'!#REF!)/732),+'Noida-01'!#REF!*(W17+U17)) -> #REF! | BK17: =IF(E17="Bundled",'Noida-01'!#REF!*V17,'Noida-01'!#REF!*V17*0.85) -> #REF! | BL17: =+BB17*V17 -> #REF! | BM17: =+#REF!*V17 -> #REF! | BN17: =+BG17-BM17 -> #REF! | BO17: =+BH17-BI17 -> #REF! | BP17: =+BN17+BO17 -> #REF! | BQ17: =+V17 -> #REF! | BR17: =+BB17 -> #REF! | BS17: =IF(E17="Bundled",BK17-BI17,AO17-BI17) -> #REF! | BT17: =IF(E17="Bundled",+(BD17-#REF!)*V17,(AM17+AN17)-V17*#REF!) -> #REF! | BU17: =+BS17+BT17 -> #REF! | BV17: =+BS17/$BQ17 -> #REF! | BW17: =+BT17/$BQ17 -> #REF! | BX17: =+BU17/$BQ17 -> #REF!
A18: L6 | B18: L6-B-33 | C18: DEHRADUN E NET SOLUTIONS (P) LTD. | D18: Rated | E18: Bundled | F18: Rack | G18: Uncaged | H18: =IF(F18="Rack","No of Racks",(IF(F18="Space","Sq Ft","U Space"))) -> No of Racks | I18: 1 | J18: 1 | K18: =I18-J18 -> 0 | L18: 1 | N18: =(442500)/12 -> 36875 | O18: =D18 -> Rated | P18: KVA | Q18: 3.5 | R18: 3.33 | S18: =Q18-R18 -> 0.17 | U18: =IF(S18<=0,0,(IF(O18="Rated",(S18+T18)*'Noida-01'!#REF!,(S18+T18)))) -> #REF! | V18: =IF(O18="Rated",Q18*'Noida-01'!#REF!,Q18) -> #REF! | W18: 2.41 | X18: =IF((S18*-1)>0, (S18*-1), 0) -> 0 | Y18: =90000/12 -> 7500 | Z18: =E18 -> Bundled | AF18: =IF(AE18="No of Seats","No of Seats",(IF(AE18="Space","Sq Ft",""))) | AI18: =AG18-AH18 -> 0 | AM18: =N18*L18 -> 36875 | AN18: =Y18*X18 -> 0 | AO18: =AD18*AC18*AA18 -> 0 | AP18: =AL18*AJ18 -> 0 | AR18: =SUBTOTAL(9,AM18:AQ18) -> 36875 | AZ18: =IF(F18="Rack",AR18/I18,0)+IF(F18="U Space",AR18*40/I18,0)+IF(F18="Space",AR18*30/I18,0) -> 36875 | BA18: =+AR18/V18 -> #REF! | BB18: =+($AM18+$AN18+$AO18-BI18)/$V18 -> #REF! | BC18: =+($AM18+$AN18+$AO18-BJ18)/$V18 -> #REF! | BD18: =+($AM18+$AN18+IF(E18="Bundled",0,V18*0.85*AA18*AC18*30.5*24)-BK18)/$V18 -> #REF! | BF18: =+AM18+AN18+AO18 -> 36875 | BG18: =+BF18-BH18 -> #REF! | BH18: =IF(E18="Bundled",MIN(V18*'Noida-01'!#REF!*(1+#REF!),BF18),AO18) -> #REF! | BI18: =IF($AD18>0,$AD18*'Noida-01'!#REF!*'Noida-01'!#REF!*(1+'Noida-01'!#REF!*(20/'Noida-01'!#REF!)/732),'Noida-01'!#REF!*W18) -> #REF! | BJ18: =IF($AD18>0,$AD18*'Noida-01'!#REF!*'Noida-01'!#REF!*(1+'Noida-01'!#REF!*(20/'Noida-01'!#REF!)/732),+'Noida-01'!#REF!*(W18+U18)) -> #REF! | BK18: =IF(E18="Bundled",'Noida-01'!#REF!*V18,'Noida-01'!#REF!*V18*0.85) -> #REF! | BL18: =+BB18*V18 -> #REF! | BM18: =+#REF!*V18 -> #REF! | BN18: =+BG18-BM18 -> #REF! | BO18: =+BH18-BI18 -> #REF! | BP18: =+BN18+BO18 -> #REF! | BQ18: =+V18 -> #REF! | BR18: =+BB18 -> #REF! | BS18: =IF(E18="Bundled",BK18-BI18,AO18-BI18) -> #REF! | BT18: =IF(E18="Bundled",+(BD18-#REF!)*V18,(AM18+AN18)-V18*#REF!) -> #REF! | BU18: =+BS18+BT18 -> #REF! | BV18: =+BS18/$BQ18 -> #REF! | BW18: =+BT18/$BQ18 -> #REF! | BX18: =+BU18/$BQ18 -> #REF!
A19: L6 | B19: L6-D-03 | C19: EMINENCE SOFTECH PVT LTD | D19: Subscribed | E19: Metered | F19: Rack | G19: Uncaged | H19: =IF(F19="Rack","No of Racks",(IF(F19="Space","Sq Ft","U Space"))) -> No of Racks | I19: 1 | J19: 1 | K19: =I19-J19 -> 0 | L19: 1 | N19: =(270000)/12 -> 22500 | O19: =D19 -> Subscribed | P19: KW | Q19: 3 | R19: =W19 -> 0.037634409 | S19: =Q19-R19 -> 2.9623656 | U19: =IF(S19<=0,0,(IF(O19="Rated",(S19+T19)*'Noida-01'!#REF!,(S19+T19)))) -> 2.9623656 | V19: =IF(O19="Rated",Q19*'Noida-01'!#REF!,Q19) -> 3 | W19: =AD19/31/24 -> 0.037634409 | X19: =IF((S19*-1)>0, (S19*-1), 0) -> 0 | Y19: =95000/12 -> 7916.6667 | Z19: =E19 -> Metered | AA19: 1 | AB19: Fixed | AC19: 17 | AD19: 28 | AI19: =AG19-AH19 -> 0 | AL19: =(0)/12 -> 0 | AM19: =N19*L19 -> 22500 | AN19: =Y19*X19 -> 0 | AO19: =AD19*AC19*AA19 -> 476 | AP19: =AL19*AJ19 -> 0 | AQ19: =0/12 -> 0 | AR19: =SUBTOTAL(9,AM19:AQ19) -> 22976 | AZ19: =IF(F19="Rack",AR19/I19,0)+IF(F19="U Space",AR19*40/I19,0)+IF(F19="Space",AR19*30/I19,0) -> 22976 | BA19: =+AR19/V19 -> 7658.6667 | BB19: =+($AM19+$AN19+$AO19-BI19)/$V19 -> #REF! | BC19: =+($AM19+$AN19+$AO19-BJ19)/$V19 -> #REF! | BD19: =+($AM19+$AN19+IF(E19="Bundled",0,V19*0.85*AA19*AC19*30.5*24)-BK19)/$V19 -> #REF! | BF19: =+AM19+AN19+AO19 -> 22976 | BG19: =+BF19-BH19 -> 22500 | BH19: =IF(E19="Bundled",MIN(V19*'Noida-01'!#REF!*(1+#REF!),BF19),AO19) -> 476 | BI19: =IF($AD19>0,$AD19*'Noida-01'!#REF!*'Noida-01'!#REF!*(1+'Noida-01'!#REF!*(20/'Noida-01'!#REF!)/732),'Noida-01'!#REF!*W19) -> #REF! | BJ19: =IF($AD19>0,$AD19*'Noida-01'!#REF!*'Noida-01'!#REF!*(1+'Noida-01'!#REF!*(20/'Noida-01'!#REF!)/732),+'Noida-01'!#REF!*(W19+U19)) -> #REF! | BK19: =IF(E19="Bundled",'Noida-01'!#REF!*V19,'Noida-01'!#REF!*V19*0.85) -> #REF! | BL19: =+BB19*V19 -> #REF! | BM19: =+#REF!*V19 -> #REF! | BN19: =+BG19-BM19 -> #REF! | BO19: =+BH19-BI19 -> #REF! | BP19: =+BN19+BO19 -> #REF! | BQ19: =+V19 -> 3 | BR19: =+BB19 -> #REF! | BS19: =IF(E19="Bundled",BK19-BI19,AO19-BI19) -> #REF! | BT19: =IF(E19="Bundled",+(BD19-#REF!)*V19,(AM19+AN19)-V19*#REF!) -> #REF! | BU19: =+BS19+BT19 -> #REF! | BV19: =+BS19/$BQ19 -> #REF! | BW19: =+BT19/$BQ19 -> #REF! | BX19: =+BU19/$BQ19 -> #REF!
A20: L7 | B20: L7-F-26 to L7-F-29 | C20: NEXTRA ONLINE SERVICES PRIVATE LIMITED | D20: Subscribed | E20: Metered | F20: Rack | G20: Uncaged | H20: =IF(F20="Rack","No of Racks",(IF(F20="Space","Sq Ft","U Space"))) -> No of Racks | I20: 4 | J20: 4 | K20: =I20-J20 -> 0 | L20: 4 | N20: =(31100) -> 31100 | O20: =D20 -> Subscribed | P20: KW | Q20: 16.6 | R20: =W20 -> 6.8954167 | S20: =Q20-R20 -> 9.7045833 | U20: =IF(S20<=0,0,(IF(O20="Rated",(S20+T20)*'Noida-01'!#REF!,(S20+T20)))) -> 9.7045833 | V20: =IF(O20="Rated",Q20*'Noida-01'!#REF!,Q20) -> 16.6 | W20: =AD20/30/24 -> 6.8954167 | X20: =IF((S20*-1)>0, (S20*-1), 0) -> 0 | Y20: =0/12 -> 0 | Z20: =E20 -> Metered | AA20: 1 | AB20: Fixed | AC20: 0 | AD20: 4964.7 | AI20: =AG20-AH20 -> 0 | AL20: =(0)/12 -> 0 | AM20: =N20*L20 -> 124400 | AN20: =Y20*X20 -> 0 | AO20: =AD20*AC20*AA20 -> 0 | AP20: =AL20*AJ20 -> 0 | AQ20: =0/12 -> 0 | AR20: =SUBTOTAL(9,AM20:AQ20) -> 124400 | AZ20: =IF(F20="Rack",AR20/I20,0)+IF(F20="U Space",AR20*40/I20,0)+IF(F20="Space",AR20*30/I20,0) -> 31100 | BA20: =+AR20/V20 -> 7493.9759 | BB20: =+($AM20+$AN20+$AO20-BI20)/$V20 -> #REF! | BC20: =+($AM20+$AN20+$AO20-BJ20)/$V20 -> #REF! | BD20: =+($AM20+$AN20+IF(E20="Bundled",0,V20*0.85*AA20*AC20*30.5*24)-BK20)/$V20 -> #REF! | BF20: =+AM20+AN20+AO20 -> 124400 | BG20: =+BF20-BH20 -> 124400 | BH20: =IF(E20="Bundled",MIN(V20*'Noida-01'!#REF!*(1+#REF!),BF20),AO20) -> 0 | BI20: =IF($AD20>0,$AD20*'Noida-01'!#REF!*'Noida-01'!#REF!*(1+'Noida-01'!#REF!*(20/'Noida-01'!#REF!)/732),'Noida-01'!#REF!*W20) -> #REF! | BJ20: =IF($AD20>0,$AD20*'Noida-01'!#REF!*'Noida-01'!#REF!*(1+'Noida-01'!#REF!*(20/'Noida-01'!#REF!)/732),+'Noida-01'!#REF!*(W20+U20)) -> #REF! | BK20: =IF(E20="Bundled",'Noida-01'!#REF!*V20,'Noida-01'!#REF!*V20*0.85) -> #REF! | BL20: =+BB20*V20 -> #REF! | BM20: =+#REF!*V20 -> #REF! | BN20: =+BG20-BM20 -> #REF! | BO20: =+BH20-BI20 -> #REF! | BP20: =+BN20+BO20 -> #REF! | BQ20: =+V20 -> 16.6 | BR20: =+BB20 -> #REF! | BS20: =IF(E20="Bundled",BK20-BI20,AO20-BI20) -> #REF! | BT20: =IF(E20="Bundled",+(BD20-#REF!)*V20,(AM20+AN20)-V20*#REF!) -> #REF! | BU20: =+BS20+BT20 -> #REF! | BV20: =+BS20/$BQ20 -> #REF! | BW20: =+BT20/$BQ20 -> #REF! | BX20: =+BU20/$BQ20 -> #REF!
A21: L5 | B21: Server Hall 5A L5A-04-11 | C21: NESECURE TELECOM | D21: Rated | E21: Bundled | F21: U space | G21: Uncaged | H21: =IF(F21="Rack","No of Racks",(IF(F21="Space","Sq Ft","U Space"))) -> U Space | I21: 6 | J21: 6 | K21: =I21-J21 -> 0 | L21: 6 | N21: =120000/12/6 -> 1666.6667 | O21: =D21 -> Rated | P21: KVA | Q21: 1 | R21: 0.05 | S21: =Q21-R21 -> 0.95 | U21: =IF(S21<=0,0,(IF(O21="Rated",(S21+T21)*$S$20,(S21+T21)))) -> 9.2193542 | V21: =IF(O21="Rated",Q21*$S$20,Q21) -> 9.7045833 | X21: =IF((S21*-1)>0, (S21*-1), 0) -> 0 | Y21: =110000/12 -> 9166.6667 | Z21: =E21 -> Bundled | AF21: =IF(AE21="No of Seats","No of Seats",(IF(AE21="Space","Sq Ft",""))) | AI21: =AG21-AH21 -> 0 | AM21: =N21*L21 -> 10000 | AN21: =Y21*X21 -> 0 | AO21: =AD21*AC21*AA21 -> 0 | AP21: =AL21*AJ21 -> 0 | AQ21: 0 | AR21: =SUBTOTAL(9,AM21:AQ21) -> 10000 | AZ21: =IF(F21="Rack",AR21/I21,0)+IF(F21="U Space",AR21*40/I21,0)+IF(F21="Space",AR21*30/I21,0) -> 66666.667 | BA21: =+AR21/V21 -> 1030.4409 | BB21: =+($AK21+$AL21+$AM21-BI21)/$T21 -> #VALUE! | BC21: =+($AK21+$AL21+$AM21-BJ21)/$T21 -> #VALUE! | BD21: =+($AK21+$AL21+IF(E21="Bundled",0,V21*0.85*AA21*AC21*30.5*24)-BK21)/$T21 -> #VALUE! | BF21: =+AM21+AN21+AO21 -> 10000 | BG21: =+BF21-BH21 -> #VALUE! | BH21: =IF(E21="Bundled",MIN(V21*$AB$20*(1+$K$2),BF21),AO21) -> #VALUE! | BI21: =IF($AB21>0,$AB21*$Y$20*$AA$20*(1+$AD$20*(20/$AA$20)/732),$AB$20*W21) -> #VALUE! | BJ21: =IF($AB21>0,$AB21*$Y$20*$AA$20*(1+$AD$20*(20/$AA$20)/732),+$AB$20*(W21+U21)) -> #VALUE! | BK21: =IF(E21="Bundled",$AB$20*V21,$AB$20*V21*0.85) -> #VALUE! | BL21: =+BB21*V21 -> #VALUE! | BM21: =+$J$2*V21 -> 0 | BN21: =+BG21-BM21 -> #VALUE! | BO21: =+BH21-BI21 -> #VALUE! | BP21: =+BN21+BO21 -> #VALUE! | BQ21: =+V21 -> 9.7045833 | BR21: =+BB21 -> #VALUE! | BS21: =IF(E21="Bundled",BK21-BI21,AO21-BI21) -> #VALUE! | BT21: =IF(E21="Bundled",+(BD21-$J$2)*V21,(AM21+AN21)-V21*$J$2) -> #VALUE! | BU21: =+BS21+BT21 -> #VALUE! | BV21: =+BS21/$BO21 -> #VALUE! | BW21: =+BT21/$BO21 -> #VALUE! | BX21: =+BU21/$BO21 -> #VALUE!
A22: L4 | B22: L4-E-27 & L4-E-28 | C22: CLOUDFLARE INC | D22: Subscribed | E22: Bundled | F22: Rack | G22: Uncaged | H22: =IF(F22="Rack","No of Racks",(IF(F22="Space","Sq Ft","U Space"))) -> No of Racks | I22: 2 | J22: 2 | K22: =I22-J22 -> 0 | L22: 2 | N22: 1840 | O22: =D22 -> Subscribed | P22: KVA | Q22: 14.36 | R22: =W22/0.9 -> 8.0506327 | S22: =Q22-R22 -> 6.3093673 | U22: =IF(S22<=0,0,(IF(O22="Rated",(S22+T22)*$V$1,(S22+T22)))) -> 6.3093673 | V22: =IF(O22="Rated",Q22*$V$1,Q22) -> 14.36 | W22: =AD22/30/24 -> 7.2455694 | X22: =IF((S22*-1)>0, (S22*-1), 0) -> 0 | Y22: 250 | Z22: =E22 -> Bundled | AA22: 1 | AB22: Fixed | AC22: 0 | AD22: 5216.81 | AI22: =AG22-AH22 -> 0 | AM22: =N22*L22 -> 3680 | AN22: =Y22*X22 -> 0 | AO22: =AD22*AC22*AA22 -> 0 | AP22: =AL22*AJ22 -> 0 | AQ22: 0 | AR22: =SUBTOTAL(9,AM22:AQ22) -> 3680 | AT22: 121000084 | AZ22: =IF(F22="Rack",AR22/I22,0)+IF(F22="U Space",AR22*40/I22,0)+IF(F22="Space",AR22*30/I22,0) -> 1840 | BA22: =+AR22/V22 -> 256.26741 | BB22: =+($AN22+$AO22+$AP22-BI22)/$W22 -> #VALUE! | BC22: =+($AN22+$AO22+$AP22-BJ22)/$W22 -> #VALUE! | BD22: =+($AN22+$AO22+IF(E22="Bundled",0,V22*0.85*AA22*AC22*30.5*24)-BK22)/$W22 -> #VALUE! | BF22: =+AM22+AN22+AO22 -> 3680 | BG22: =+BF22-BH22 -> #VALUE! | BH22: =IF(E22="Bundled",MIN(V22*$AE$1*(1+#REF!),BF22),AO22) -> #VALUE! | BI22: =IF($AE22>0,$AE22*$AB$1*$AD$1*(1+$AG$1*(20/$AD$1)/732),$AE$1*W22) -> #VALUE! | BJ22: =IF($AE22>0,$AE22*$AB$1*$AD$1*(1+$AG$1*(20/$AD$1)/732),+$AE$1*(W22+U22)) -> #VALUE! | BK22: =IF(E22="Bundled",$AE$1*V22,$AE$1*V22*0.85) -> #VALUE! | BL22: =+BB22*V22 -> #VALUE! | BM22: =+#REF!*V22 -> #REF! | BN22: =+BG22-BM22 -> #VALUE! | BO22: =+BH22-BI22 -> #VALUE! | BP22: =+BN22+BO22 -> #VALUE! | BQ22: =+V22 -> 14.36 | BR22: =+BB22 -> #VALUE! | BS22: =IF(E22="Bundled",BK22-BI22,AO22-BI22) -> #VALUE! | BT22: =IF(E22="Bundled",+(BD22-#REF!)*V22,(AM22+AN22)-V22*#REF!) -> #VALUE! | BU22: =+BS22+BT22 -> #VALUE! | BV22: =+BS22/$BR22 -> #VALUE! | BW22: =+BT22/$BR22 -> #VALUE! | BX22: =+BU22/$BR22 -> #VALUE!
A23: L6 | B23: L6-D-01, L6-D-02 | C23: Cloudflare | D23: Subscribed | E23: Bundled | F23: Rack | G23: Uncaged | H23: =IF(F23="Rack","No of Racks",(IF(F23="Space","Sq Ft","U Space"))) -> No of Racks | I23: 2 | J23: 2 | K23: =I23-J23 -> 0 | L23: 2 | N23: 1840 | O23: =D23 -> Subscribed | P23: KW | Q23: 13 | R23: =W23 -> 0 | S23: =Q23-R23 -> 13 | U23: =IF(S23<=0,0,(IF(O23="Rated",(S23+T23)*$V$1,(S23+T23)))) -> 13 | V23: =IF(O23="Rated",Q23*$V$1,Q23) -> 13 | W23: =AD23/31/24 -> 0 | X23: =IF((S23*-1)>0, (S23*-1), 0) -> 0 | Y23: 283 | Z23: =E23 -> Bundled | AA23: 1 | AB23: Fixed | AC23: 0 | AD23: 0 | AI23: =AG23-AH23 -> 0 | AM23: =N23*L23 -> 3680 | AN23: =Y23*X23 -> 0 | AO23: =AD23*AC23*AA23 -> 0 | AP23: =AL23*AJ23 -> 0 | AQ23: 0 | AR23: =SUBTOTAL(9,AM23:AQ23) -> 3680 | AZ23: =IF(F23="Rack",AR23/I23,0)+IF(F23="U Space",AR23*40/I23,0)+IF(F23="Space",AR23*30/I23,0) -> 1840 | BA23: =+AR23/V23 -> 283.07692 | BB23: =+($AN23+$AO23+$AP23-BI23)/$W23 -> #VALUE! | BC23: =+($AN23+$AO23+$AP23-BJ23)/$W23 -> #VALUE! | BD23: =+($AN23+$AO23+IF(E23="Bundled",0,V23*0.85*AA23*AC23*30.5*24)-BK23)/$W23 -> #VALUE! | BF23: =+AM23+AN23+AO23 -> 3680 | BG23: =+BF23-BH23 -> #VALUE! | BH23: =IF(E23="Bundled",MIN(V23*$AE$1*(1+#REF!),BF23),AO23) -> #VALUE! | BI23: =IF($AE23>0,$AE23*$AB$1*$AD$1*(1+$AG$1*(20/$AD$1)/732),$AE$1*W23) -> #VALUE! | BJ23: =IF($AE23>0,$AE23*$AB$1*$AD$1*(1+$AG$1*(20/$AD$1)/732),+$AE$1*(W23+U23)) -> #VALUE! | BK23: =IF(E23="Bundled",$AE$1*V23,$AE$1*V23*0.85) -> #VALUE! | BL23: =+BB23*V23 -> #VALUE! | BM23: =+#REF!*V23 -> #REF! | BN23: =+BG23-BM23 -> #VALUE! | BO23: =+BH23-BI23 -> #VALUE! | BP23: =+BN23+BO23 -> #VALUE! | BQ23: =+V23 -> 13 | BR23: =+BB23 -> #VALUE! | BS23: =IF(E23="Bundled",BK23-BI23,AO23-BI23) -> #VALUE! | BT23: =IF(E23="Bundled",+(BD23-#REF!)*V23,(AM23+AN23)-V23*#REF!) -> #VALUE! | BU23: =+BS23+BT23 -> #VALUE! | BV23: =+BS23/$BR23 -> #VALUE! | BW23: =+BT23/$BR23 -> #VALUE! | BX23: =+BU23/$BR23 -> #VALUE!
A24: L4 | B24: L4-F-30 | C24: CP WHOLESALE INDIA PVT LTD | D24: Rated | E24: Metered | F24: Rack | G24: Uncaged | H24: =IF(F24="Rack","No of Racks",(IF(F24="Space","Sq Ft","U Space"))) -> No of Racks | I24: 1 | J24: 1 | K24: =I24-J24 -> 0 | L24: 1 | N24: =(360000)/12 -> 30000 | O24: =D24 -> Rated | P24: KVA | Q24: 9 | R24: 9 | S24: =Q24-R24 -> 0 | U24: =IF(S24<=0,0,(IF(O24="Rated",(S24+T24)*$V$1,(S24+T24)))) -> 0 | V24: =IF(O24="Rated",Q24*$V$1,Q24) -> #VALUE! | W24: =AD24/31/24 -> 0.81201613 | X24: =IF((S24*-1)>0, (S24*-1), 0) -> 0 | Y24: 0 | Z24: =E24 -> Metered | AA24: 1 | AB24: Fixed | AC24: 17 | AD24: 604.14 | AF24: =IF(AE24="No of Seats","No of Seats",(IF(AE24="Space","Sq Ft",""))) | AI24: =AG24-AH24 -> 0 | AM24: =N24*L24 -> 30000 | AN24: =Y24*X24 -> 0 | AO24: =AD24*AC24*AA24 -> 10270.38 | AP24: =AL24*AJ24 -> 0 | AQ24: =600000/12 -> 50000 | AR24: =SUBTOTAL(9,AM24:AQ24) -> 90270.38 | AT24: 721005527 & 711120937 | AZ24: =IF(F24="Rack",AR24/I24,0)+IF(F24="U Space",AR24*40/I24,0)+IF(F24="Space",AR24*30/I24,0) -> 90270.38 | BA24: =+AR24/V24 -> #VALUE! | BB24: =+($AM24+$AN24+$AO24-BI24)/$V24 -> #VALUE! | BC24: =+($AM24+$AN24+$AO24-BJ24)/$V24 -> #VALUE! | BD24: =+($AM24+$AN24+IF(E24="Bundled",0,V24*0.85*AA24*AC24*30.5*24)-BK24)/$V24 -> #VALUE! | BF24: =+AM24+AN24+AO24 -> 40270.38 | BG24: =+BF24-BH24 -> 30000 | BH24: =IF(E24="Bundled",MIN(V24*$AE$1*(1+#REF!),BF24),AO24) -> 10270.38 | BI24: =IF($AD24>0,$AD24*$AB$1*$AD$1*(1+$AG$1*(20/$AD$1)/732),$AE$1*W24) -> #VALUE! | BJ24: =IF($AD24>0,$AD24*$AB$1*$AD$1*(1+$AG$1*(20/$AD$1)/732),+$AE$1*(W24+U24)) -> #VALUE! | BK24: =IF(E24="Bundled",$AE$1*V24,$AE$1*V24*0.85) -> #VALUE! | BL24: =+BB24*V24 -> #VALUE! | BM24: =+#REF!*V24 -> #REF! | BN24: =+BG24-BM24 -> #REF! | BO24: =+BH24-BI24 -> #VALUE! | BP24: =+BN24+BO24 -> #REF! | BQ24: =+V24 -> #VALUE! | BR24: =+BB24 -> #VALUE! | BS24: =IF(E24="Bundled",BK24-BI24,AO24-BI24) -> #VALUE! | BT24: =IF(E24="Bundled",+(BD24-#REF!)*V24,(AM24+AN24)-V24*#REF!) -> #VALUE! | BU24: =+BS24+BT24 -> #VALUE! | BV24: =+BS24/$BQ24 -> #VALUE! | BW24: =+BT24/$BQ24 -> #VALUE! | BX24: =+BU24/$BQ24 -> #VALUE!
A25: L4 | B25: L4-E-33 | C25: CP WHOLESALE INDIA PVT LTD | D25: Rated | E25: Metered | F25: Rack | G25: Uncaged | H25: =IF(F25="Rack","No of Racks",(IF(F25="Space","Sq Ft","U Space"))) -> No of Racks | I25: 1 | J25: 1 | K25: 0 | L25: 1 | N25: =(750000+320000+225000)/12/3 -> 35972.222 | O25: =D25 -> Rated | P25: KVA | Q25: 8 | R25: 10.62 | S25: =Q25-R25 -> -2.62 | U25: =IF(S25<=0,0,(IF(O25="Rated",(S25+T25)*$V$1,(S25+T25)))) -> 0 | V25: =IF(O25="Rated",Q25*$V$1,Q25) -> #VALUE! | W25: =AD25/31/24 -> 4.4697849 | X25: =IF((S25*-1)>0, (S25*-1), 0) -> 2.62 | Y25: =90000/12 -> 7500 | Z25: =E25 -> Metered | AA25: 1 | AB25: Fixed | AC25: 15.75 | AD25: 3325.52 | AF25: =IF(AE25="No of Seats","No of Seats",(IF(AE25="Space","Sq Ft",""))) | AI25: =AG25-AH25 -> 0 | AM25: =N25*L25 -> 35972.222 | AN25: =Y25*X25 -> 19650 | AO25: =AD25*AC25*AA25 -> 52376.94 | AP25: =AL25*AJ25 -> 0 | AQ25: =600000/12 -> 50000 | AR25: =SUBTOTAL(9,AM25:AQ25) -> 157999.16 | AT25: 721005527 & 711120937 | AZ25: =IF(F25="Rack",AR25/I25,0)+IF(F25="U Space",AR25*40/I25,0)+IF(F25="Space",AR25*30/I25,0) -> 157999.16 | BA25: =+AR25/V25 -> #VALUE! | BB25: =+($AM25+$AN25+$AO25-BI25)/$V25 -> #VALUE! | BC25: =+($AM25+$AN25+$AO25-BJ25)/$V25 -> #VALUE! | BD25: =+($AM25+$AN25+IF(E25="Bundled",0,V25*0.85*AA25*AC25*30.5*24)-BK25)/$V25 -> #VALUE! | BF25: =+AM25+AN25+AO25 -> 107999.16 | BG25: =+BF25-BH25 -> 55622.222 | BH25: =IF(E25="Bundled",MIN(V25*$AE$1*(1+#REF!),BF25),AO25) -> 52376.94 | BI25: =IF($AD25>0,$AD25*$AB$1*$AD$1*(1+$AG$1*(20/$AD$1)/732),$AE$1*W25) -> #VALUE! | BJ25: =IF($AD25>0,$AD25*$AB$1*$AD$1*(1+$AG$1*(20/$AD$1)/732),+$AE$1*(W25+U25)) -> #VALUE! | BK25: =IF(E25="Bundled",$AE$1*V25,$AE$1*V25*0.85) -> #VALUE! | BL25: =+BB25*V25 -> #VALUE! | BM25: =+#REF!*V25 -> #REF! | BN25: =+BG25-BM25 -> #REF! | BO25: =+BH25-BI25 -> #VALUE! | BP25: =+BN25+BO25 -> #REF! | BQ25: =+V25 -> #VALUE! | BR25: =+BB25 -> #VALUE! | BS25: =IF(E25="Bundled",BK25-BI25,AO25-BI25) -> #VALUE! | BT25: =IF(E25="Bundled",+(BD25-#REF!)*V25,(AM25+AN25)-V25*#REF!) -> #VALUE! | BU25: =+BS25+BT25 -> #VALUE! | BV25: =+BS25/$BQ25 -> #VALUE! | BW25: =+BT25/$BQ25 -> #VALUE! | BX25: =+BU25/$BQ25 -> #VALUE!
A26: L7 | B26: L7-A-15, L7-A-16, L7-A-17 & L7-A-18 | C26: Stackpath | D26: Subscribed | E26: Metered | F26: Rack | G26: Caged | H26: =IF(F26="Rack","No of Racks",(IF(F26="Space","Sq Ft","U Space"))) -> No of Racks | I26: 4 | J26: 4 | K26: =I26-J26 -> 0 | L26: 4 | N26: =(0)/12 -> 0 | O26: =D26 -> Subscribed | P26: KW | Q26: 30 | R26: =W26 -> 12.166935 | S26: =Q26-R26 -> 17.833065 | U26: =IF(S26<=0,0,(IF(O26="Rated",(S26+T26)*'Noida-01'!#REF!,(S26+T26)))) -> 17.833065 | V26: =IF(O26="Rated",Q26*'Noida-01'!#REF!,Q26) -> 30 | W26: =AD26/31/24 -> 12.166935 | X26: =IF((S26*-1)>0, (S26*-1), 0) -> 0 | Y26: =0/12 -> 0 | Z26: =E26 -> Metered | AB26: Fixed | AC26: 0 | AD26: 9052.2 | AI26: =AG26-AH26 -> 0 | AL26: =(0)/12 -> 0 | AM26: =N26*L26 -> 0 | AN26: =Y26*X26 -> 0 | AO26: =AD26*AC26*AA26 -> 0 | AP26: =AL26*AJ26 -> 0 | AQ26: =0/12 -> 0 | AR26: =SUBTOTAL(9,AM26:AQ26) -> 0 | AZ26: =IF(F26="Rack",AR26/I26,0)+IF(F26="U Space",AR26*40/I26,0)+IF(F26="Space",AR26*30/I26,0) -> 0 | BA26: =+AR26/V26 -> 0 | BB26: =+($AM26+$AN26+$AO26-BI26)/$V26 -> #REF! | BC26: =+($AM26+$AN26+$AO26-BJ26)/$V26 -> #REF! | BD26: =+($AM26+$AN26+IF(E26="Bundled",0,V26*0.85*AA26*AC26*30.5*24)-BK26)/$V26 -> #REF! | BF26: =+AM26+AN26+AO26 -> 0 | BG26: =+BF26-BH26 -> 0 | BH26: =IF(E26="Bundled",MIN(V26*'Noida-01'!#REF!*(1+#REF!),BF26),AO26) -> 0 | BI26: =IF($AD26>0,$AD26*'Noida-01'!#REF!*'Noida-01'!#REF!*(1+'Noida-01'!#REF!*(20/'Noida-01'!#REF!)/732),'Noida-01'!#REF!*W26) -> #REF! | BJ26: =IF($AD26>0,$AD26*'Noida-01'!#REF!*'Noida-01'!#REF!*(1+'Noida-01'!#REF!*(20/'Noida-01'!#REF!)/732),+'Noida-01'!#REF!*(W26+U26)) -> #REF! | BK26: =IF(E26="Bundled",'Noida-01'!#REF!*V26,'Noida-01'!#REF!*V26*0.85) -> #REF! | BL26: =+BB26*V26 -> #REF! | BM26: =+#REF!*V26 -> #REF! | BN26: =+BG26-BM26 -> #REF! | BO26: =+BH26-BI26 -> #REF! | BP26: =+BN26+BO26 -> #REF! | BQ26: =+V26 -> 30 | BR26: =+BB26 -> #REF! | BS26: =IF(E26="Bundled",BK26-BI26,AO26-BI26) -> #REF! | BT26: =IF(E26="Bundled",+(BD26-#REF!)*V26,(AM26+AN26)-V26*#REF!) -> #REF! | BU26: =+BS26+BT26 -> #REF! | BV26: =+BS26/$BQ26 -> #REF! | BW26: =+BT26/$BQ26 -> #REF! | BX26: =+BU26/$BQ26 -> #REF!
A27: L4 | B27: L4-E-23 | C27: iBOSS, INC. | D27: Rated | E27: Bundled | F27: Rack | G27: Uncaged | H27: =IF(F27="Rack","No of Racks",(IF(F27="Space","Sq Ft","U Space"))) -> No of Racks | I27: 1 | J27: 1 | K27: =I27-J27 -> 0 | L27: 1 | N27: =(13000*70)/12 -> 75833.333 | O27: =D27 -> Rated | P27: KVA | Q27: 5 | R27: 19.62 | S27: =Q27-R27 -> -14.62 | U27: =IF(S27<=0,0,(IF(O27="Rated",(S27+T27)*'Noida-01'!#REF!,(S27+T27)))) -> 0 | V27: =IF(O27="Rated",Q27*'Noida-01'!#REF!,Q27) -> #REF! | W27: 5.49 | X27: =IF((S27*-1)>0, (S27*-1), 0) -> 14.62 | Y27: =0/12 -> 0 | Z27: =E27 -> Bundled | AI27: =AG27-AH27 -> 0 | AL27: =(0)/12 -> 0 | AM27: =N27*L27 -> 75833.333 | AN27: =Y27*X27 -> 0 | AO27: =AD27*AC27*AA27 -> 0 | AP27: =AL27*AJ27 -> 0 | AQ27: =((19700+2850)*70)/12 -> 131541.67 | AR27: =SUBTOTAL(9,AM27:AQ27) -> 207375 | AT27: 121000513 | AU27: 43700 | AV27: 3 | AW27: 44795 | AZ27: =IF(F27="Rack",AR27/I27,0)+IF(F27="U Space",AR27*40/I27,0)+IF(F27="Space",AR27*30/I27,0) -> 207375 | BA27: =+AR27/V27 -> #REF! | BB27: =+($AM27+$AN27+$AO27-BI27)/$V27 -> #REF! | BC27: =+($AM27+$AN27+$AO27-BJ27)/$V27 -> #REF! | BD27: =+($AM27+$AN27+IF(E27="Bundled",0,V27*0.85*AA27*AC27*30.5*24)-BK27)/$V27 -> #REF! | BF27: =+AM27+AN27+AO27 -> 75833.333 | BG27: =+BF27-BH27 -> #REF! | BH27: =IF(E27="Bundled",MIN(V27*'Noida-01'!#REF!*(1+#REF!),BF27),AO27) -> #REF! | BI27: =IF($AD27>0,$AD27*'Noida-01'!#REF!*'Noida-01'!#REF!*(1+'Noida-01'!#REF!*(20/'Noida-01'!#REF!)/732),'Noida-01'!#REF!*W27) -> #REF! | BJ27: =IF($AD27>0,$AD27*'Noida-01'!#REF!*'Noida-01'!#REF!*(1+'Noida-01'!#REF!*(20/'Noida-01'!#REF!)/732),+'Noida-01'!#REF!*(W27+U27)) -> #REF! | BK27: =IF(E27="Bundled",'Noida-01'!#REF!*V27,'Noida-01'!#REF!*V27*0.85) -> #REF! | BL27: =+BB27*V27 -> #REF! | BM27: =+#REF!*V27 -> #REF! | BN27: =+BG27-BM27 -> #REF! | BO27: =+BH27-BI27 -> #REF! | BP27: =+BN27+BO27 -> #REF! | BQ27: =+V27 -> #REF! | BR27: =+BB27 -> #REF! | BS27: =IF(E27="Bundled",BK27-BI27,AO27-BI27) -> #REF! | BT27: =IF(E27="Bundled",+(BD27-#REF!)*V27,(AM27+AN27)-V27*#REF!) -> #REF! | BU27: =+BS27+BT27 -> #REF! | BV27: =+BS27/$BQ27 -> #REF! | BW27: =+BT27/$BQ27 -> #REF! | BX27: =+BU27/$BQ27 -> #REF!
A28: L7 | B28: L7-F-25 | C28: ONEOTT INTERTAINMENT LTD | D28: Subscribed | E28: Metered | F28: Rack | G28: Uncaged | H28: =IF(F28="Rack","No of Racks",(IF(F28="Space","Sq Ft","U Space"))) -> No of Racks | I28: 1 | J28: 1 | K28: =I28-J28 -> 0 | L28: 1 | O28: =D28 -> Subscribed | P28: KW | Q28: 2.5 | S28: =Q28-R28 -> 2.5 | U28: =IF(S28<=0,0,(IF(O28="Rated",(S28+T28)*$V$1,(S28+T28)))) -> 2.5 | V28: =IF(O28="Rated",Q28*$V$1,Q28) -> 2.5 | W28: =AD28/31/24 -> 0 | X28: =IF((S28*-1)>0, (S28*-1), 0) -> 0 | Z28: =E28 -> Metered
A29: L5 | B29: L5A-01-06 | C29: STAR BROADBAND SERVICES I PVT LTD | D29: Rated | E29: Bundled | F29: U space | G29: Uncaged | H29: =IF(F29="Rack","No of Racks",(IF(F29="Space","Sq Ft","U Space"))) -> U Space | I29: 1 | J29: 1 | K29: =I29-J29 -> 0 | L29: 1 | N29: =55000/12 -> 4583.3333 | O29: =D29 -> Rated | P29: KVA | Q29: 0.25 | R29: 0.26 | S29: =Q29-R29 -> -0.01 | U29: =IF(S29<=0,0,(IF(O29="Rated",(S29+T29)*$V$1,(S29+T29)))) -> 0 | V29: =IF(O29="Rated",Q29*$V$1,Q29) -> #VALUE! | X29: =IF((S29*-1)>0, (S29*-1), 0) -> 0.01 | Y29: =90000/12 -> 7500 | Z29: =E29 -> Bundled | AF29: =IF(AE29="No of Seats","No of Seats",(IF(AE29="Space","Sq Ft",""))) | AI29: =AG29-AH29 -> 0 | AM29: =N29*L29 -> 4583.3333 | AN29: =Y29*X29 -> 75 | AO29: =AD29*AC29*AA29 -> 0 | AP29: =AL29*AJ29 -> 0 | AQ29: =(10000+140000)/12 -> 12500 | AR29: =SUBTOTAL(9,AM29:AQ29) -> 17158.333 | AT29: 121000867 | AZ29: =IF(F29="Rack",AR29/I29,0)+IF(F29="U Space",AR29*40/I29,0)+IF(F29="Space",AR29*30/I29,0) -> 686333.33 | BA29: =+AR29/V29 -> #VALUE! | BB29: =+($AM29+$AN29+$AO29-BI29)/$V29 -> #VALUE! | BC29: =+($AM29+$AN29+$AO29-BJ29)/$V29 -> #VALUE! | BD29: =+($AM29+$AN29+IF(E29="Bundled",0,V29*0.85*AA29*AC29*30.5*24)-BK29)/$V29 -> #VALUE! | BF29: =+AM29+AN29+AO29 -> 4658.3333 | BG29: =+BF29-BH29 -> #VALUE! | BH29: =IF(E29="Bundled",MIN(V29*$AE$1*(1+#REF!),BF29),AO29) -> #VALUE! | BI29: =IF($AD29>0,$AD29*$AB$1*$AD$1*(1+$AG$1*(20/$AD$1)/732),$AE$1*W29) -> #VALUE! | BJ29: =IF($AD29>0,$AD29*$AB$1*$AD$1*(1+$AG$1*(20/$AD$1)/732),+$AE$1*(W29+U29)) -> #VALUE! | BK29: =IF(E29="Bundled",$AE$1*V29,$AE$1*V29*0.85) -> #VALUE! | BL29: =+BB29*V29 -> #VALUE! | BM29: =+#REF!*V29 -> #REF! | BN29: =+BG29-BM29 -> #VALUE! | BO29: =+BH29-BI29 -> #VALUE! | BP29: =+BN29+BO29 -> #VALUE! | BQ29: =+V29 -> #VALUE! | BR29: =+BB29 -> #VALUE! | BS29: =IF(E29="Bundled",BK29-BI29,AO29-BI29) -> #VALUE! | BT29: =IF(E29="Bundled",+(BD29-#REF!)*V29,(AM29+AN29)-V29*#REF!) -> #VALUE! | BU29: =+BS29+BT29 -> #VALUE! | BV29: =+BS29/$BQ29 -> #VALUE! | BW29: =+BT29/$BQ29 -> #VALUE! | BX29: =+BU29/$BQ29 -> #VALUE!
A30: L5 | B30: L5A-02-01 | C30: PRACTION NETWORKS PVT LTD | D30: Rated | E30: Bundled | F30: U space | G30: Uncaged | H30: =IF(F30="Rack","No of Racks",(IF(F30="Space","Sq Ft","U Space"))) -> U Space | I30: 4 | J30: 4 | K30: =I30-J30 -> 0 | L30: 4 | N30: =35000/12 -> 2916.6667 | O30: =D30 -> Rated | P30: KVA | Q30: 1 | R30: 0.17 | S30: =Q30-R30 -> 0.83 | U30: =IF(S30<=0,0,(IF(O30="Rated",(S30+T30)*$V$1,(S30+T30)))) -> #VALUE! | V30: =IF(O30="Rated",Q30*$V$1,Q30) -> #VALUE! | X30: =IF((S30*-1)>0, (S30*-1), 0) -> 0 | Y30: =110000/12 -> 9166.6667 | Z30: =E30 -> Bundled | AF30: =IF(AE30="No of Seats","No of Seats",(IF(AE30="Space","Sq Ft",""))) | AI30: =AG30-AH30 -> 0 | AM30: =N30*L30 -> 11666.667 | AN30: =Y30*X30 -> 0 | AO30: =AD30*AC30*AA30 -> 0 | AP30: =AL30*AJ30 -> 0 | AQ30: =(100000+60000)/12 -> 13333.333 | AR30: =SUBTOTAL(9,AM30:AQ30) -> 25000 | AT30: 121000185 | AZ30: =IF(F30="Rack",AR30/I30,0)+IF(F30="U Space",AR30*40/I30,0)+IF(F30="Space",AR30*30/I30,0) -> 250000 | BA30: =+AR30/V30 -> #VALUE! | BB30: =+($AM30+$AN30+$AO30-BI30)/$V30 -> #VALUE! | BC30: =+($AM30+$AN30+$AO30-BJ30)/$V30 -> #VALUE! | BD30: =+($AM30+$AN30+IF(E30="Bundled",0,V30*0.85*AA30*AC30*30.5*24)-BK30)/$V30 -> #VALUE! | BF30: =+AM30+AN30+AO30 -> 11666.667 | BG30: =+BF30-BH30 -> #VALUE! | BH30: =IF(E30="Bundled",MIN(V30*$AE$1*(1+#REF!),BF30),AO30) -> #VALUE! | BI30: =IF($AD30>0,$AD30*$AB$1*$AD$1*(1+$AG$1*(20/$AD$1)/732),$AE$1*W30) -> #VALUE! | BJ30: =IF($AD30>0,$AD30*$AB$1*$AD$1*(1+$AG$1*(20/$AD$1)/732),+$AE$1*(W30+U30)) -> #VALUE! | BK30: =IF(E30="Bundled",$AE$1*V30,$AE$1*V30*0.85) -> #VALUE! | BL30: =+BB30*V30 -> #VALUE! | BM30: =+#REF!*V30 -> #REF! | BN30: =+BG30-BM30 -> #VALUE! | BO30: =+BH30-BI30 -> #VALUE! | BP30: =+BN30+BO30 -> #VALUE! | BQ30: =+V30 -> #VALUE! | BR30: =+BB30 -> #VALUE! | BS30: =IF(E30="Bundled",BK30-BI30,AO30-BI30) -> #VALUE! | BT30: =IF(E30="Bundled",+(BD30-#REF!)*V30,(AM30+AN30)-V30*#REF!) -> #VALUE! | BU30: =+BS30+BT30 -> #VALUE! | BV30: =+BS30/$BQ30 -> #VALUE! | BW30: =+BT30/$BQ30 -> #VALUE! | BX30: =+BU30/$BQ30 -> #VALUE!
